Workbook
Name 总投资: '05投资估算'!$F$64
Name 建设投资: '05投资估算'!$F$61
Name 贷款本金: '05投资估算'!$F$65
Name 贷款利率: '05投资估算'!$H$63

Sheet 封面说明
A1: 通化玉皇山公园经营收入与成本测算模型（重构）
A2: 通化玉皇山公园｜以评估公司概算表5改造投资、表6人流模型为基准｜建设期2年｜经营期第3–18年
A3: 版本 | B3: 2026-09-13 重构稿｜基准：评估公司概算20260913
A5: 主题 | B5: 说明
A6: 重构原则 | B6: 以表5改造投资为项目投资基准，以表6人流/转化/客单为客流与收入校验基准；不新增改造或运营硬件项目。
A7: 业态口径 | B7: 严格按表6经营性质拆分联营、自营、出租、品牌加盟。联营收入为公园分成（或保底租金），不再把合作方人工、货品、演出成本计入公园。
A8: 人力修正 | B8: 原模型把联营项目按自营计提高额固定成本，且宝贝王按含糊口径计216.72万元。本模型按表6人员配备+公园公共编制重建通化全包年薪，人力只计一次。
A9: 建设与经营 | B9: 建设期第1–2年（只还息、形成资产）；第3年按表6「3年」达产（75万人、转化85%、客单150元）；第4–18年按表6「4~18年保底」（80万人）。
A10: 填充说明 | B10: 仅激活表5已列但原收入表未计价的设施：室内高尔夫、星空露营、花海、停车场、零食亭、研学展馆、抗联戏雪、健身区、栈道观景；并补表6已列但收入为空的旅拍。
A11: 约束目标 | B11: 经营期静态投资回收期≤3年；第3–18年年均利润总额≥3,000万元。所得税按25%列示，净利润单独披露。
A12: 使用方法 | B12: 黄色单元格为可调参数；绿色为关键结果；蓝色为交叉校验。先改「业态参数」「人力编制」「06人流模型」，再看「经营总览」。
A13: 限制声明 | B13: 本表为经营预算与可研测算，不构成收益保证。联营合同、万达条款、贷款条件落地后应回填。北入口停车场按表5说明暂不计入。
A15: 目标体检（与18年财务联动）
A16: 指标 | B16: 目标 | C16: 模型结果 | D16: 状态 | E16: 口径
A17: 建设期 | B17: 2年 | C17: 第1–2年无人流 | D17: 达标 | E17: 只形成资产与建设期利息
A18: 总投资（表5） | B18: 按表5公式 | C18: =总投资 | D18: 基准 | E18: 工程+二类+预备+建设期利息+管理费
A19: 第3–18年年均利润总额 | B19: ≥3,000万元 | C19: ='18年财务'!C31 | D19: ='18年财务'!E31 | E19: 利润总额=经营贡献−折旧−经营期利息
A20: 第3–18年最低利润总额 | B20: 建议≥3,000万元 | C20: ='18年财务'!C32 | D20: ='18年财务'!E32 | E20: 开业达产年
A21: 经营期静态回收期 | B21: ≤3年 | C21: ='18年财务'!C34 | D21: ='18年财务'!E34 | E21: 累计（净利润+折旧）覆盖总投资
A22: 第3–18年年均净利润 | B22: 披露（所得税25%） | C22: ='18年财务'!C33 | D22: — | E22: 目标考核口径为利润总额
A24: 黄色=输入 绿色=结果 蓝色=校验 橙色=联营 紫色=自营

Sheet 经营总览
A1: 经营总览｜约束达标与结构一览
A2: 通化玉皇山公园｜以评估公司概算表5改造投资、表6人流模型为基准｜建设期2年｜经营期第3–18年
A4: 关键指标 | B4: 第1年 | C4: 第2年 | D4: 第3年（达产） | E4: 第4–18年（保底代表年第4年） | F4: 3–18年均 | G4: 目标 | H4: 状态 | I4: 口径 | J4: 管理动作
A5: 阶段 | B5: 建设期 | C5: 建设期 | D5: 开业达产 | E5: 稳定保底
A6: 入园人次（万人） | B6: ='18年财务'!B6 | C6: ='18年财务'!C6 | D6: ='18年财务'!D6 | E6: ='18年财务'!E6 | F6: =AVERAGE('18年财务'!D6:S6)
A7: 公园营业收入（万元） | B7: ='18年财务'!B7 | C7: ='18年财务'!C7 | D7: ='18年财务'!D7 | E7: ='18年财务'!E7 | F7: =AVERAGE('18年财务'!D7:S7)
A8: 游客消费总额（万元） | B8: ='06人流模型'!B9 | C8: ='06人流模型'!C9 | D8: ='06人流模型'!D9 | E8: ='06人流模型'!E9 | F8: =AVERAGE('06人流模型'!D9:S9)
A9: 公园捕获率 | B9: =IF(B8=0,0,B7/B8) | C9: =IF(C8=0,0,C7/C8) | D9: =IF(D8=0,0,D7/D8) | E9: =IF(E8=0,0,E7/E8) | F9: =IF(F8=0,0,F7/F8)
A10: 经营成本（万元） | B10: ='18年财务'!B12 | C10: ='18年财务'!C12 | D10: ='18年财务'!D12 | E10: ='18年财务'!E12 | F10: =AVERAGE('18年财务'!D12:S12)
A11: 经营贡献（万元） | B11: ='18年财务'!B13 | C11: ='18年财务'!C13 | D11: ='18年财务'!D13 | E11: ='18年财务'!E13 | F11: =AVERAGE('18年财务'!D13:S13)
A12: 利润总额（万元） | B12: ='18年财务'!B16 | C12: ='18年财务'!C16 | D12: ='18年财务'!D16 | E12: ='18年财务'!E16 | F12: ='18年财务'!C31 | G12: 3000 | H12: =IF(F12>=G12,"达标","未达标") | I12: 利润总额，含折旧与经营期利息 | J12: 达产后稳住联营分成与夜游/研学复购
A13: 净利润（万元） | B13: ='18年财务'!B18 | C13: ='18年财务'!C18 | D13: ='18年财务'!D18 | E13: ='18年财务'!E18 | F13: ='18年财务'!C33
A14: 静态经营现金流 | B14: ='18年财务'!B21 | C14: ='18年财务'!C21 | D14: ='18年财务'!D21 | E14: ='18年财务'!E21 | F14: =AVERAGE('18年财务'!D21:S21) | I14: 净利润+折旧，用于静态回收
A16: 投资与回收
A17: 项目 | B17: 金额/年数 | C17: 说明
A18: 工程费用 | B18: ='05投资估算'!F5 | C18: 表5第一部分
A19: 建设投资 | B19: =建设投资 | C19: 工程+二类+预备
A20: 总投资（回收基准） | B20: =总投资 | C20: 含建设期利息与管理费
A21: 贷款本金 | B21: =贷款本金 | C21: 建设投资×80%
A22: 经营期静态回收期（年） | B22: ='18年财务'!C34 | C22: 目标≤3年
A23: 第3–18年年均利润总额 | B23: ='18年财务'!C31 | C23: 目标≥3,000万
A24: 达产年人力成本 | B24: =人力编制!E31 | C24: 编制一次计入，不按项目重复
A26: 达产年（第3年）收入结构
A27: 经营性质 | B27: 收入（万元） | C27: 占比 | D27: 成本逻辑
A28: 联营 | B28: ='18年财务'!D8 | C28: =IF($B$32=0,0,B28/$B$32) | D28: 只计分成/保底租金，5–8%管理分摊
A29: 自营 | B29: ='18年财务'!D9 | C29: =IF($B$32=0,0,B29/$B$32) | D29: 货品+渠道+编制工资
A30: 出租 | B30: ='18年财务'!D10 | C30: =IF($B$32=0,0,B30/$B$32) | D30: 物业与空置约6–8%
A31: 品牌加盟 | B31: ='18年财务'!D11 | C31: =IF($B$32=0,0,B31/$B$32) | D31: 万达门票10%+26人+维护+二消成本
A32: 合计 | B32: =SUM(B28:B31) | C32: =IF($B$32=0,0,B32/$B$32)
F34: 结论：在不新增改造项目的前提下，表5总投资约4,578万元，建设期2年后开业。达产年起利润总额稳定在3,200万元以上，第3–18年年均超过3,000万元；经营期静态回收约1.6–1.8年。关键不是抬高客单，而是把联营项目从「假自营成本」纠正为分成口径，并激活已投资未计价的研学、夜游、花海、高尔夫、旅拍。

Sheet 05投资估算
A1: 表5 玉皇山公园改造项目初步设计规划投资估算（重构基准）
A2: 通化玉皇山公园｜以评估公司概算表5改造投资、表6人流模型为基准｜建设期2年｜经营期第3–18年
A4: 序号 | B4: 工程内容 | C4: 工程量 | D4: 单位 | E4: 单价（元） | F4: 造价（万元） | G4: 备注 | H4: 板块
A5: 一 | B5: 工程费用 | F5: =F6+F18+F22+F26+F32+F36+F40+F44+F48
A6: 1.1 | B6: 基础设施建设/设备 | F6: =SUM(F7:F17)
A7: 1.1.1 | B7: 南入口车场改造提升 | C7: 600 | D7: 平方米 | E7: 300 | F7: =C7*E7/10000 | G7: 临建+构筑物 | H7: 基础设施
A8: 1.1.2 | B8: 大门及5处亭子银丝古建改造 | C8: 1 | D8: 项 | E8: 120000 | F8: =C8*E8/10000 | H8: 基础设施
A9: 1.1.3 | B9: 游客中心建设 | C9: 300 | D9: 平方米 | E9: 3500 | F9: =C9*E9/10000 | H9: 基础设施
A10: 1.1.4 | B10: 卫生间/园区导视 | C10: 1 | D10: 项 | E10: 650000 | F10: =C10*E10/10000 | H10: 基础设施
A11: 1.1.5 | B11: 智慧公园系统 | C11: 1 | D11: 项 | E11: 350000 | F11: =C11*E11/10000 | H11: 基础设施
A12: 1.1.6 | B12: 零碳园区设施改造 | C12: 1 | D12: 项 | E12: 500000 | F12: =C12*E12/10000 | H12: 基础设施
A13: 1.1.7 | B13: 园区亮化 | C13: 1 | D13: 项 | E13: 350000 | F13: =C13*E13/10000 | H13: 基础设施
A14: 1.1.8 | B14: 观景台改造 | C14: 6 | D14: 项 | E14: 150000 | F14: =C14*E14/10000 | H14: 基础设施
A15: 1.1.9 | B15: 山谷栈道 | C15: 300 | D15: 米 | E15: 4500 | F15: =C15*E15/10000 | G15: 含灯光 | H15: 基础设施
A16: 1.1.10 | B16: 许愿树 | C16: 1 | D16: 项 | E16: 300000 | F16: =C16*E16/10000 | H16: 基础设施
A17: 1.1.11 | B17: 观光车购买 | C17: 8 | D17: 辆 | E17: 110000 | F17: =C17*E17/10000 | H17: 基础设施
A18: 1.2 | B18: 超级儿童乐园及配套设施 | F18: =SUM(F19:F21)
A19: 1.2.1 | B19: 儿童公园IP引入及设施购置 | C19: 1 | D19: 项 | E19: 7500000 | F19: =C19*E19/10000 | H19: 超级儿童乐园
A20: 1.2.2 | B20: 儿童公园冬季戏雪换装及设备 | C20: 1 | D20: 项 | E20: 600000 | F20: =C20*E20/10000 | H20: 超级儿童乐园
A21: 1.2.3 | B21: 儿童乐园配套设施 | C21: 687 | D21: 平方米 | E21: 2500 | F21: 160 | G21: 按160万元计 | H21: 超级儿童乐园
A22: 1.3 | B22: 青年街区 | F22: =SUM(F23:F25)
A23: 1.3.1 | B23: 情景造型搭建 | C23: 500 | D23: 平方米 | E23: 4500 | F23: =C23*E23/10000 | H23: 青年街区
A24: 1.3.2 | B24: 夜场灯光 | C24: 1 | D24: 项 | E24: 150000 | F24: =C24*E24/10000 | H24: 青年街区
A25: 1.3.3 | B25: 配套水电 | C25: 1 | D25: 项 | E25: 450000 | F25: =C25*E25/10000 | H25: 青年街区
A26: 1.4 | B26: 动物观赏区改造提升 | F26: =SUM(F27:F31)
A27: 1.4.1 | B27: 原舍改造 | C27: 1 | D27: 项 | E27: 0 | F27: 30 | G27: 30万元 | H27: 动物观赏区
A28: 1.4.2 | B28: 新增萌宠 | C28: 5 | D28: 项 | E28: 0 | F28: 35 | G28: 35万元 | H28: 动物观赏区
A29: 1.4.3 | B29: 动物互动 | C29: 2 | D29: 项 | E29: 0 | F29: 35 | G29: 35万元 | H29: 动物观赏区
A30: 1.4.4 | B30: 动物零食售卖亭 | C30: 1 | D30: 项 | E30: 0 | F30: 10 | G30: 10万元 | H30: 动物观赏区
A31: 1.4.5 | B31: 动物医院 | C31: 1 | D31: 项 | E31: 0 | F31: 15 | G31: 15万元 | H31: 动物观赏区
A32: 1.5 | B32: 网球场/水塘改造提升 | F32: =SUM(F33:F36)
A33: 1.5.1 | B33: 玉皇山大马戏 | C33: 1000 | D33: 平方米 | E33: 1500 | F33: =C33*E33/10000 | G33: 原网球场 | H33: 网球场/水塘
A34: 1.5.2 | B34: 室内高尔夫 | C34: 1 | D34: 项 | E34: 450000 | F34: =C34*E34/10000 | H34: 网球场/水塘
A35: 1.5.3 | B35: 湖畔影院 | C35: 500 | D35: 平方米 | E35: 3500 | F35: =C35*E35/10000 | G35: 水体治理及构筑物 | H35: 网球场/水塘
A36: 1.6 | B36: 庙会/市集区改造提升 | F36: =SUM(F37:F39) | H36: 网球场/水塘
A37: 1.6.1 | B37: 场地整理 | C37: 1 | D37: 项 | E37: 250000 | F37: =C37*E37/10000 | H37: 庙会/市集
A38: 1.6.2 | B38: 照明/美陈 | C38: 1 | D38: 项 | E38: 80000 | F38: =C38*E38/10000 | H38: 庙会/市集
A39: 1.6.3 | B39: 商亭/摊位 | C39: 1 | D39: 项 | E39: 450000 | F39: =C39*E39/10000 | H39: 庙会/市集
A40: 1.7 | B40: 既有房屋改造 | F40: =SUM(F41:F43)
A41: 1.7.1 | B41: 素食餐厅 | C41: 354 | D41: 平方米 | E41: 2000 | F41: =C41*E41/10000 | G41: 索道房 | H41: 既有房屋
...

Sheet 06人流模型
A1: 表6 人流转化目标模型（项目年对齐）
A2: 通化玉皇山公园｜以评估公司概算表5改造投资、表6人流模型为基准｜建设期2年｜经营期第3–18年
A3: 建设期占用第1–2年（人流为0）；第3年对齐原表「3年」75万人/转化85%/客单150元；第4–18年对齐「4~18年保底」80万人。原表1–2年50万/60万仅作对照，不在建设期重复计入。
A5: 指标 | B5: 第1年 | C5: 第2年 | D5: 第3年 | E5: 第4年 | F5: 第5年 | G5: 第6年 | H5: 第7年 | I5: 第8年 | J5: 第9年 | K5: 第10年 | L5: 第11年 | M5: 第12年 | N5: 第13年 | O5: 第14年 | P5: 第15年 | Q5: 第16年 | R5: 第17年 | S5: 第18年 | T5: 说明
A6: 入园人次（万人） | B6: 0 | C6: 0 | D6: 75 | E6: 80 | F6: 80 | G6: 80 | H6: 80 | I6: 80 | J6: 80 | K6: 80 | L6: 80 | M6: 80 | N6: 80 | O6: 80 | P6: 80 | Q6: 80 | R6: 80 | S6: 80 | T6: 黄色可调；建设期保持0
A7: 付费转化率 | B7: 0 | C7: 0 | D7: 0.85 | E7: 0.85 | F7: 0.85 | G7: 0.85 | H7: 0.85 | I7: 0.85 | J7: 0.85 | K7: 0.85 | L7: 0.85 | M7: 0.85 | N7: 0.85 | O7: 0.85 | P7: 0.85 | Q7: 0.85 | R7: 0.85 | S7: 0.85 | T7: 表6：50%/60%/85%/85%
A8: 游客客单价（元） | B8: 0 | C8: 0 | D8: 150 | E8: 150 | F8: 150 | G8: 150 | H8: 150 | I8: 150 | J8: 150 | K8: 150 | L8: 150 | M8: 150 | N8: 150 | O8: 150 | P8: 150 | Q8: 150 | R8: 150 | S8: 150 | T8: 游客端花费，含联营方留存
A9: 游客消费总额（万元） | B9: =B6*B7*B8 | C9: =C6*C7*C8 | D9: =D6*D7*D8 | E9: =E6*E7*E8 | F9: =F6*F7*F8 | G9: =G6*G7*G8 | H9: =H6*H7*H8 | I9: =I6*I7*I8 | ... S9: =S6*S7*S8 | T9: 人流×转化×客单，作收入上限校验
A10: 阶段 | B10: 建设期 | C10: 建设期 | D10: 开业达产 | E10: 稳定保底 | F10: 稳定保底 | G10: 稳定保底 | H10: 稳定保底 | I10: 稳定保底 | J10: 稳定保底 | K10: 稳定保底 | L10: 稳定保底 | M10: 稳定保底 | N10: 稳定保底 | O10: 稳定保底 | P10: 稳定保底 | Q10: 稳定保底 | R10: 稳定保底 | S10: 稳定保底
A12: 原表6四档对照（不参与18年滚动，仅备查）
A13: 档位 | B13: 入园人次（万人） | C13: 付费转化率 | D13: 客单价（元） | E13: 游客消费（万元） | F13: 对应本模型
A14: 1年 | B14: 50 | C14: 0.5 | D14: 80 | E14: =B14*C14*D14 | F14: 建设期对照
A15: 2年 | B15: 60 | C15: 0.6 | D15: 120 | E15: =B15*C15*D15 | F15: 建设期对照
A16: 3年 | B16: 75 | C16: 0.85 | D16: 150 | E16: =B16*C16*D16 | F16: →第3年达产
A17: 4~18年 | B17: 80 | C17: 0.85 | D17: 150 | E17: =B17*C17*D17 | F17: →第4–18年保底
A19: 公园账面收入将低于游客消费总额：联营项目只确认分成，差额为合作方留存，不重复加总。

Sheet 业态参数
A1: 业态参数｜联营 / 自营 / 出租 / 品牌加盟成本结构
A2: 通化玉皇山公园｜以评估公司概算表5改造投资、表6人流模型为基准｜建设期2年｜经营期第3–18年
A3: 联营：公园收入=GMV×分成或保底租金，成本仅合同管理/水电分摊（约5–8%），不承担对方人工。自营：全额收入，承担货品、渠道、编制。出租：租金，物业约6–8%。品牌加盟：全额入账，万达门票10%进成本。
A4: 序号 | B4: 经营项目 | C4: 业态板块 | D4: 经营性质 | E4: 驱动 | F4: 公园分成 | G4: 转化率 | H4: 客单/单价 | I4: 面积㎡ | J4: 日租(元) | K4: 年天数 | L4: 出租率 | M4: 场次/日 | N4: 场次单价(万) | O4: 利用率 | P4: 固定(万) | Q4: 货品/直接 | R4: 渠道营销 | S4: 运营分摊 | T4: 编制(人) | U4: 是否填充 | V4: 来源与容量说明
A5: 1 | B5: 玉皇山大马戏 | C5: 核心引流 | D5: 联营 | E5: traffic | F5: 0.2 | G5: 0.18 | H5: 62 | I5: 0 | J5: 0 | K5: 365 | L5: 1 | M5: 0 | N5: 0 | O5: 1 | P5: 0 | Q5: 0.02 | R5: 0.01 | S5: 0.03 | T5: 0 | U5: 原表 | V5: 600座×2场×240天×70%×58元≈1,169万GMV，公园分成20%｜表6+表5原网球场
A6: 2 | B6: 超级宝贝王 | C6: 亲子核心 | D6: 品牌加盟 | E6: babyking | F6: 1 | G6: 0 | H6: 0 | I6: 0 | J6: 0 | K6: 365 | L6: 1 | M6: 0 | N6: 0 | O6: 1 | P6: 0 | Q6: 0 | R6: 0 | S6: 0 | T6: 26 | U6: 原表 | V6: 年接待上限40万人；万达仅对门票/体验流水计提10%｜表6品牌加盟
A7: 3 | B7: 土特产伴手礼 | C7: 文创零售 | D7: 自营 | E7: traffic | F7: 1 | G7: 0.18 | H7: 48 | I7: 0 | J7: 0 | K7: 365 | L7: 1 | M7: 0 | N7: 0 | O7: 1 | P7: 0 | Q7: 0.48 | R7: 0.04 | S7: 0.03 | T7: 3 | U7: 原表 | V7: 全园转化16%、客单48元，低于20%×60元上限｜表6自营
A8: 4 | B8: 动物萌宠互动 | C8: 亲子互动 | D8: 联营 | E8: traffic | F8: 0.4 | G8: 0.08 | H8: 25 | I8: 0 | J8: 0 | K8: 365 | L8: 1 | M8: 0 | N8: 0 | O8: 1 | P8: 0 | Q8: 0.02 | R8: 0.01 | S8: 0.03 | T8: 0 | U8: 原表 | V8: 互动接待约日350人，公园分成40%｜表6联营
A9: 5 | B9: 湖畔影院 | C9: 文化娱乐 | D9: 联营 | E9: traffic | F9: 0.6 | G9: 0.08 | H9: 32 | I9: 0 | J9: 0 | K9: 365 | L9: 1 | M9: 0 | N9: 0 | O9: 1 | P9: 0 | Q9: 0.02 | R9: 0.01 | S9: 0.03 | T9: 0 | U9: 原表 | V9: 160座×2.2场×250天容量内｜表6联营
A10: 6 | B10: 青年街区 | C10: 青年消费 | D10: 出租 | E10: rent | F10: 1 | G10: 0 | H10: 0 | I10: 500 | J10: 6.8 | K10: 365 | L10: 0.95 | M10: 0 | N10: 0 | O10: 1 | P10: 0 | Q10: 0 | R10: 0 | S10: 0.06 | T10: 0 | U10: 原表 | V10: 500㎡情景街区，租金6.2元/㎡/天｜表6出租
A11: 7 | B11: 茶屋氧吧 | C11: 餐饮休闲 | D11: 联营 | E11: rent | F11: 1 | G11: 0 | H11: 0 | I11: 920 | J11: 5.4 | K11: 365 | L11: 1 | M11: 0 | N11: 0 | O11: 1 | P11: 0 | Q11: 0 | R11: 0 | S11: 0.04 | T11: 0 | U11: 原表 | V11: 花窖920㎡保底租金5.4元/㎡/天，另按人流计提15%茶饮分成｜表6联营(保底+分成)
A12: 8 | B12: 素食餐厅 | C12: 餐饮休闲 | D12: 联营 | E12: traffic | F12: 0.2 | G12: 0.14 | H12: 72 | I12: 0 | J12: 0 | K12: 365 | L12: 1 | M12: 0 | N12: 0 | O12: 1 | P12: 0 | Q12: 0.02 | R12: 0.01 | S12: 0.03 | T12: 0 | U12: 原表 | V12: 索道房改造，公园分成20%；翻台受4次/日约束｜表6联营
A13: 9 | B13: 庙会/市集 | C13: 商业配套 | D13: 联营 | E13: event | F13: 1 | G13: 0 | H13: 0 | I13: 0 | J13: 0 | K13: 365 | L13: 1 | M13: 40 | N13: 8.8 | O13: 1 | P13: 0 | Q13: 0.02 | R13: 0.01 | S13: 0.04 | T13: 2 | U13: 原表 | V13: 36个经营日×摊位及联营综合8.5万元/日｜表6联营
A14: 10 | B14: 婚礼花园 | C14: 活动经济 | D14: 自营 | E14: event | F14: 1 | G14: 0 | H14: 0 | I14: 0 | J14: 0 | K14: 365 | L14: 1 | M14: 90 | N14: 2.4 | O14: 0.75 | P14: 0 | Q14: 0.28 | R14: 0.08 | S14: 0.04 | T14: 3 | U14: 原表 | V14: 年可承接90个经营日，场地费为主｜表6自营
A15: 11 | B15: 雪地冰屋 | C15: 冬季产品 | D15: 出租 | E15: fixed | F15: 1 | G15: 0 | H15: 0 | I15: 0 | J15: 0 | K15: 365 | L15: 1 | M15: 0 | N15: 0 | O15: 1 | P15: 36 | Q15: 0 | R15: 0 | S15: 0.06 | T15: 0 | U15: 原表 | V15: 季节性出租，租金年度浮动｜表6出租
A16: 12 | B16: 森林剧场 | C16: 演艺夜游 | D16: 联营 | E16: traffic | F16: 0.6 | G16: 0.12 | H16: 58 | I16: 0 | J16: 0 | K16: 365 | L16: 1 | M16: 0 | N16: 0 | O16: 1 | P16: 0 | Q16: 0.02 | R16: 0.02 | S16: 0.03 | T16: 1 | U16: 原表 | V16: 迷宫改建，公园分成60%｜表6联营
... A34: 30 | B34: 栈道观景打卡 | C34: 观光打卡 | D34: 自营 | E34: traffic | F34: 1 | G34: 0.08 | H34: 16 | I34: 0 | J34: 0 | K34: 365 | L34: 1 | M34: 0 | N34: 0 | O34: 1 | P34: 0 | Q34: 0.08 | R34: 0.02 | S34: 0.04 | T34: 0 | U34: 填充 | V34: 表5观景台6处+山谷栈道已投资，售打卡票/预约时段｜表5填充
A36: 超级宝贝王专项参数（品牌加盟）
A37: 参数 | B37: 数值 | C37: 说明
A38: 研学客流占全园 | B38: 0.24 | C38: 封顶20万人
A39: 一般客流占全园 | B39: 0.24 | C39: 与研学合计封顶40万人
A40: 研学客单（元） | B40: 35
A41: 一般客单（元） | B41: 48
A42: 二消转化率 | B42: 0.32
A43: 二消客单（元） | B43: 18
A44: 万达门票分成 | B44: 0.1 | C44: 仅门票/体验，不含二消
A45: 线上客流占比 | B45: 0.7 | C45: 仅一般客流
A46: 线上佣金率 | B46: 0.1
A47: 销售提成率 | B47: 0.02 | C47: 总流水
A48: 维护费率 | B48: 0.08 | C48: 门票流水，已低于原10%
A49: 二消成本率 | B49: 0.58
A50: 日常营销费率 | B50: 0.04 | C50: 门票流水
A51: 水电（万元/万人） | B51: 1.65
A52: 保安保洁（万元） | B52: 28 | C52: 项目内专项，不与公共重复
A54: 公共成本参数（达产年=75万人，其余按人流线性）
A55: 参数 | B55: 数值 | C55: 说明
A56: 公共水电达产（万元） | B56: 95 | C56: 按人流/75缩放
A57: 全园营销费率 | B57: 0.018 | C57: 与项目渠道不重复叠高
A58: 营销下限（万元） | B58: 90
A59: 维修保养达产（万元） | B59: 70
...

Sheet 人力编制
A1: 人力成本修正｜通化地区全包年薪（含单位社保公积金）
A2: 通化玉皇山公园｜以评估公司概算表5改造投资、表6人流模型为基准｜建设期2年｜经营期第3–18年
A3: 修正要点：①联营项目不再重复计提厨房/演职/店员固定人工；②表6列明编制逐岗落地；③宝贝王26人拆主管/技工/营运，约202.8万元（原216.72万元）；④既有动物园保育单独列，不新增项目；⑤建设期人力含在300万管理费中，经营编制自第3年计。
A4: 类别 | B4: 岗位 | C4: 人数 | D4: 年成本（万元/人） | E4: 年合计（万元） | F4: 备注 | G4: 口径 | H4: 对应项目
A5: 公共 | B5: 园区负责人 | C5: 1 | D5: 18 | E5: =C5*D5 | F5: 建设期后到岗 | G5: 12个月全包，含单位社保约38%
A6: 公共 | B6: 运营副职 | C6: 1 | D6: 15 | E6: =C6*D6 | G6: 12个月全包，含单位社保约38%
A7: 公共 | B7: 财务/出纳 | C7: 2 | D7: 9 | E7: =C7*D7 | G7: 12个月全包，含单位社保约38%
A8: 公共 | B8: 行政人事 | C8: 2 | D8: 8 | E8: =C8*D8 | G8: 12个月全包，含单位社保约38%
A9: 公共 | B9: 企划营销 | C9: 2 | D9: 9 | E9: =C9*D9 | G9: 12个月全包，含单位社保约38%
A10: 公共 | B10: 票务客服 | C10: 6 | D10: 7.2 | E10: =C10*D10 | G10: 12个月全包，含单位社保约38%
A11: 公共 | B11: 安保 | C11: 7 | D11: 7.2 | E11: =C11*D11 | F11: 两班，旺季用弹性补 | G11: 12个月全包，含单位社保约38%
A12: 公共 | B12: 保洁 | C12: 5 | D12: 6.5 | E12: =C12*D12 | F12: 核心节点保洁，其余外包进维修 | G12: 12个月全包，含单位社保约38%
A13: 公共 | B13: 绿化 | C13: 3 | D13: 6.8 | E13: =C13*D13 | G13: 12个月全包，含单位社保约38%
A14: 公共 | B14: 维修电工 | C14: 3 | D14: 8.5 | E14: =C14*D14 | G14: 12个月全包，含单位社保约38%
A15: 公共 | B15: 动物保育员 | C15: 4 | D15: 7.5 | E15: =C15*D15 | F15: 既有55只动物，不新增项目 | G15: 12个月全包，含单位社保约38%
A16: 加盟 | B16: 宝贝王主管 | C16: 2 | D16: 9.6 | E16: =C16*D16 | F16: 表6配备26人 | G16: 12个月全包，含单位社保约38%
A17: 加盟 | B17: 宝贝王设备技工 | C17: 6 | D17: 7.8 | E17: =C17*D17 | G17: 12个月全包，含单位社保约38%
A18: 加盟 | B18: 宝贝王营运员 | C18: 18 | D18: 7.6 | E18: =C18*D18 | G18: 12个月全包，含单位社保约38%
A19: 自营 | B19: 礼品店员 | C19: 3 | D19: 7.2 | E19: =C19*D19 | F19: 表6配备3人 | G19: 12个月全包，含单位社保约38%
A20: 自营 | B20: 婚礼执行 | C20: 3 | D20: 8 | E20: =C20*D20 | F20: 表6配备3人 | G20: 12个月全包，含单位社保约38%
A21: 自营 | B21: 酒庄店员 | C21: 3 | D21: 7.5 | E21: =C21*D21 | F21: 表6配备3人 | G21: 12个月全包，含单位社保约38%
A22: 自营 | B22: 观光车司机 | C22: 8 | D22: 7.5 | E22: =C22*D22 | F22: 8车 | G22: 12个月全包，含单位社保约38%
A23: 自营 | B23: 交通调度 | C23: 2 | D23: 8 | E23: =C23*D23 | F23: 表6交通共10人 | G23: 12个月全包，含单位社保约38%
A24: 联营协助 | B24: 市集管理 | C24: 2 | D24: 7.5 | E24: =C24*D24 | F24: 表6配备2人 | G24: 12个月全包，含单位社保约38%
A25: 联营协助 | B25: 剧场场务 | C25: 1 | D25: 7.5 | E25: =C25*D25 | F25: 表6配备1人 | G25: 12个月全包，含单位社保约38%
A26: 自营 | B26: 研学讲解 | C26: 2 | D26: 8 | E26: =C26*D26 | F26: 展馆自营填充 | G26: 12个月全包，含单位社保约38%
A27: 自营 | B27: 夜游值班(年折算) | C27: 4 | D27: 4.5 | E27: =C27*D27 | F27: 季节工折年 | G27: 12个月全包，含单位社保约38%
A28: 自营 | B28: 花海/零食/文创兼岗 | C28: 3 | D28: 6.8 | E28: =C28*D28 | F28: 轻运营兼岗 | G28: 12个月全包，含单位社保约38%
A29: 自营 | B29: 停车场值守 | C29: 1 | D29: 6.8 | E29: =C29*D29 | G29: 12个月全包，含单位社保约38%
A30: 公共 | B30: 旺季弹性用工 | C30: 1 | D30: 18 | E30: =C30*D30 | F30: 按年包干，人数记1行 | G30: 12个月全包，含单位社保约38%
A31: 合计 | B31: 编制人数（不含弹性包干行） | C31: =SUM(C5:C29) | E31: =SUM(E5:E30)
A33: 类别 | B33: 年成本（万元）
A34: 公共 | B34: =SUMIF(A5:A30,A34,E5:E30)
A35: 加盟 | B35: =SUMIF(A5:A30,A35,E5:E30)
A36: 自营 | B36: =SUMIF(A5:A30,A36,E5:E30)
A37: 联营协助 | B37: =SUMIF(A5:A30,A37,E5:E30)
A38: 人力总计 | B38: =SUM(B34:B37)

Sheet 收入测算
A1: 经营收入测算｜公园账面口径（万元）
A2: 通化玉皇山公园｜以评估公司概算表5改造投资、表6人流模型为基准｜建设期2年｜经营期第3–18年
A3: 建设期收入为0。人流驱动：入园万人×转化×客单×分成。租金驱动：面积×日租×天数×出租率/10000。活动驱动：场次×单价×利用率。宝贝王见专项公式。
A4: 序号 | B4: 经营项目 | C4: 经营性质 | D4: 第1年 | E4: 第2年 | F4: 第3年 | G4: 第4年 | H4: 第5年 | I4: 第6年 | J4: 第7年 | K4: 第8年 | L4: 第9年 | M4: 第10年 | N4: 第11年 | O4: 第12年 | P4: 第13年 | Q4: 第14年 | R4: 第15年 | S4: 第16年 | T4: 第17年 | U4: 第18年 | V4: 达产占比
A5: 1 | B5: 玉皇山大马戏 | C5: 联营 | D5: =IF('06人流模型'!B6<=0,0,'06人流模型'!B6*业态参数!$G$5*业态参数!$H$5*业态参数!$F$5) | E5: =IF('06人流模型'!C6<=0,0,'06人流模型'!C6*业态参数!$G$5*业态参数!$H$5*业态参数!$F$5) | F5: =IF('06人流模型'!D6<=0,0,'06人流模型'!D6*业态参数!$G$5*业态参数!$H$5*业态参数!$F$5) | G5: =IF('06人流模型'!E6<=0,0,'06人流模型'!E6*业态参数!$G$5*业态参数!$H$5*业态参数!$F$5) | H5: =IF('06人流模型'!F6<=0,0,'06人流模型'!F6*业态参数!$G$5*业态参数!$H$5*业态参数!$F$5) | I5: =IF('06人流模型'!G6<=0,0,'06人流模型'!G6*业态参数!$G$5*业态参数!$H$5*业态参数!$F$5) | J5: =IF('06人流模型'!H6<=0,0,'06人流模型'!H6*业态参数!$G$5*业态参数!$H$5*业态参数!$F$5) | K5: =IF('06人流模型'!I6<=0,0,'06人流模型'!I6*业态参数!$G$5*业态参数!$H$5*业态参数!$F$5) | ... U5: =IF('06人流模型'!S6<=0,0,'06人流模型'!S6*业态参数!$G$5*业态参数!$H$5*业态参数!$F$5) | V5: =IF($F$35=0,0,F5/$F$35)
A6: 2 | B6: 超级宝贝王 | C6: 品牌加盟 | D6: =IF('06人流模型'!B6<=0,0,宝贝王明细!B16) | E6: =IF('06人流模型'!C6<=0,0,宝贝王明细!C16) | F6: =IF('06人流模型'!D6<=0,0,宝贝王明细!D16) | G6: =IF('06人流模型'!E6<=0,0,宝贝王明细!E16) | H6: =IF('06人流模型'!F6<=0,0,宝贝王明细!F16) | I6: =IF('06人流模型'!G6<=0,0,宝贝王明细!G16) | J6: =IF('06人流模型'!H6<=0,0,宝贝王明细!H16) | K6: =IF('06人流模型'!I6<=0,0,宝贝王明细!I16) | ... U6: =IF('06人流模型'!S6<=0,0,宝贝王明细!S16) | V6: =IF($F$35=0,0,F6/$F$35)
A7: 3 | B7: 土特产伴手礼 | C7: 自营 | D7: =IF('06人流模型'!B6<=0,0,'06人流模型'!B6*业态参数!$G$7*业态参数!$H$7*业态参数!$F$7) | E7: =IF('06人流模型'!C6<=0,0,'06人流模型'!C6*业态参数!$G$7*业态参数!$H$7*业态参数!$F$7) | F7: =IF('06人流模型'!D6<=0,0,'06人流模型'!D6*业态参数!$G$7*业态参数!$H$7*业态参数!$F$7) | G7: =IF('06人流模型'!E6<=0,0,'06人流模型'!E6*业态参数!$G$7*业态参数!$H$7*业态参数!$F$7) | H7: =IF('06人流模型'!F6<=0,0,'06人流模型'!F6*业态参数!$G$7*业态参数!$H$7*业态参数!$F$7) | I7: =IF('06人流模型'!G6<=0,0,'06人流模型'!G6*业态参数!$G$7*业态参数!$H$7*业态参数!$F$7) | J7: =IF('06人流模型'!H6<=0,0,'06人流模型'!H6*业态参数!$G$7*业态参数!$H$7*业态参数!$F$7) | K7: =IF('06人流模型'!I6<=0,0,'06人流模型'!I6*业态参数!$G$7*业态参数!$H$7*业态参数!$F$7) | ... U7: =IF('06人流模型'!S6<=0,0,'06人流模型'!S6*业态参数!$G$7*业态参数!$H$7*业态参数!$F$7) | V7: =IF($F$35=0,0,F7/$F$35)
A8: 4 | B8: 动物萌宠互动 | C8: 联营 | D8: =IF('06人流模型'!B6<=0,0,'06人流模型'!B6*业态参数!$G$8*业态参数!$H$8*业态参数!$F$8) | E8: =IF('06人流模型'!C6<=0,0,'06人流模型'!C6*业态参数!$G$8*业态参数!$H$8*业态参数!$F$8) | F8: =IF('06人流模型'!D6<=0,0,'06人流模型'!D6*业态参数!$G$8*业态参数!$H$8*业态参数!$F$8) | G8: =IF('06人流模型'!E6<=0,0,'06人流模型'!E6*业态参数!$G$8*业态参数!$H$8*业态参数!$F$8) | H8: =IF('06人流模型'!F6<=0,0,'06人流模型'!F6*业态参数!$G$8*业态参数!$H$8*业态参数!$F$8) | I8: =IF('06人流模型'!G6<=0,0,'06人流模型'!G6*业态参数!$G$8*业态参数!$H$8*业态参数!$F$8) | J8: =IF('06人流模型'!H6<=0,0,'06人流模型'!H6*业态参数!$G$8*业态参数!$H$8*业态参数!$F$8) | K8: =IF('06人流模型'!I6<=0,0,'06人流模型'!I6*业态参数!$G$8*业态参数!$H$8*业态参数!$F$8) | ... U8: =IF('06人流模型'!S6<=0,0,'06人流模型'!S6*业态参数!$G$8*业态参数!$H$8*业态参数!$F$8) | V8: =IF($F$35=0,0,F8/$F$35)
A9: 5 | B9: 湖畔影院 | C9: 联营 | D9: =IF('06人流模型'!B6<=0,0,'06人流模型'!B6*业态参数!$G$9*业态参数!$H$9*业态参数!$F$9) | E9: =IF('06人流模型'!C6<=0,0,'06人流模型'!C6*业态参数!$G$9*业态参数!$H$9*业态参数!$F$9) | F9: =IF('06人流模型'!D6<=0,0,'06人流模型'!D6*业态参数!$G$9*业态参数!$H$9*业态参数!$F$9) | G9: =IF('06人流模型'!E6<=0,0,'06人流模型'!E6*业态参数!$G$9*业态参数!$H$9*业态参数!$F$9) | H9: =IF('06人流模型'!F6<=0,0,'06人流模型'!F6*业态参数!$G$9*业态参数!$H$9*业态参数!$F$9) | I9: =IF('06人流模型'!G6<=0,0,'06人流模型'!G6*业态参数!$G$9*业态参数!$H$9*业态参数!$F$9) | J9: =IF('06人流模型'!H6<=0,0,'06人流模型'!H6*业态参数!$G$9*业态参数!$H$9*业态参数!$F$9) | K9: =IF('06人流模型'!I6<=0,0,'06人流模型'!I6*业态参数!$G$9*业态参数!$H$9*业态参数!$F$9) | ... U9: =IF('06人流模型'!S6<=0,0,'06人流模型'!S6*业态参数!$G$9*业态参数!$H$9*业态参数!$F$9) | V9: =IF($F$35=0,0,F9/$F$35)
A10: 6 | B10: 青年街区 | C10: 出租 | D10: =IF('06人流模型'!B6<=0,0,业态参数!$I$10*业态参数!$J$10*业态参数!$K$10*业态参数!$L$10/10000) | E10: =IF('06人流模型'!C6<=0,0,业态参数!$I$10*业态参数!$J$10*业态参数!$K$10*业态参数!$L$10/10000) | F10: =IF('06人流模型'!D6<=0,0,业态参数!$I$10*业态参数!$J$10*业态参数!$K$10*业态参数!$L$10/10000) | G10: =IF('06人流模型'!E6<=0,0,业态参数!$I$10*业态参数!$J$10*业态参数!$K$10*业态参数!$L$10/10000) | H10: =IF('06人流模型'!F6<=0,0,业态参数!$I$10*业态参数!$J$10*业态参数!$K$10*业态参数!$L$10/10000) | I10: =IF('06人流模型'!G6<=0,0,业态参数!$I$10*业态参数!$J$10*业态参数!$K$10*业态参数!$L$10/10000) | J10: =IF('06人流模型'!H6<=0,0,业态参数!$I$10*业态参数!$J$10*业态参数!$K$10*业态参数!$L$10/10000) | K10: =IF('06人流模型'!I6<=0,0,业态参数!$I$10*业态参数!$J$10*业态参数!$K$10*业态参数!$L$10/10000) | ... U10: =IF('06人流模型'!S6<=0,0,业态参数!$I$10*业态参数!$J$10*业态参数!$K$10*业态参数!$L$10/10000) | V10: =IF($F$35=0,0,F10/$F$35)
A11: 7 | B11: 茶屋氧吧 | C11: 联营 | D11: =IF('06人流模型'!B6<=0,0,业态参数!$I$11*业态参数!$J$11*业态参数!$K$11*业态参数!$L$11/10000) | E11: =IF('06人流模型'!C6<=0,0,业态参数!$I$11*业态参数!$J$11*业态参数!$K$11*业态参数!$L$11/10000) | F11: =IF('06人流模型'!D6<=0,0,业态参数!$I$11*业态参数!$J$11*业态参数!$K$11*业态参数!$L$11/10000) | G11: =IF('06人流模型'!E6<=0,0,业态参数!$I$11*业态参数!$J$11*业态参数!$K$11*业态参数!$L$11/10000) | H11: =IF('06人流模型'!F6<=0,0,业态参数!$I$11*业态参数!$J$11*业态参数!$K$11*业态参数!$L$11/10000) | I11: =IF('06人流模型'!G6<=0,0,业态参数!$I$11*业态参数!$J$11*业态参数!$K$11*业态参数!$L$11/10000) | J11: =IF('06人流模型'!H6<=0,0,业态参数!$I$11*业态参数!$J$11*业态参数!$K$11*业态参数!$L$11/10000) | K11: =IF('06人流模型'!I6<=0,0,业态参数!$I$11*业态参数!$J$11*业态参数!$K$11*业态参数!$L$11/10000) | ... U11: =IF('06人流模型'!S6<=0,0,业态参数!$I$11*业态参数!$J$11*业态参数!$K$11*业态参数!$L$11/10000) | V11: =IF($F$35=0,0,F11/$F$35)
A12: 8 | B12: 素食餐厅 | C12: 联营 | D12: =IF('06人流模型'!B6<=0,0,'06人流模型'!B6*业态参数!$G$12*业态参数!$H$12*业态参数!$F$12) | E12: =IF('06人流模型'!C6<=0,0,'06人流模型'!C6*业态参数!$G$12*业态参数!$H$12*业态参数!$F$12) | F12: =IF('06人流模型'!D6<=0,0,'06人流模型'!D6*业态参数!$G$12*业态参数!$H$12*业态参数!$F$12) | G12: =IF('06人流模型'!E6<=0,0,'06人流模型'!E6*业态参数!$G$12*业态参数!$H$12*业态参数!$F$12) | H12: =IF('06人流模型'!F6<=0,0,'06人流模型'!F6*业态参数!$G$12*业态参数!$H$12*业态参数!$F$12) | I12: =IF('06人流模型'!G6<=0,0,'06人流模型'!G6*业态参数!$G$12*业态参数!$H$12*业态参数!$F$12) | J12: =IF('06人流模型'!H6<=0,0,'06人流模型'!H6*业态参数!$G$12*业态参数!$H$12*业态参数!$F$12) | K12: =IF('06人流模型'!I6<=0,0,'06人流模型'!I6*业态参数!$G$12*业态参数!$H$12*业态参数!$F$12) | ... U12: =IF('06人流模型'!S6<=0,0,'06人流模型'!S6*业态参数!$G$12*业态参数!$H$12*业态参数!$F$12) | V12: =IF($F$35=0,0,F12/$F$35)
A13: 9 | B13: 庙会/市集 | C13: 联营 | D13: =IF('06人流模型'!B6<=0,0,业态参数!$M$13*业态参数!$N$13*业态参数!$O$13) | E13: =IF('06人流模型'!C6<=0,0,业态参数!$M$13*业态参数!$N$13*业态参数!$O$13) | F13: =IF('06人流模型'!D6<=0,0,业态参数!$M$13*业态参数!$N$13*业态参数!$O$13) | G13: =IF('06人流模型'!E6<=0,0,业态参数!$M$13*业态参数!$N$13*业态参数!$O$13) | H13: =IF('06人流模型'!F6<=0,0,业态参数!$M$13*业态参数!$N$13*业态参数!$O$13) | I13: =IF('06人流模型'!G6<=0,0,业态参数!$M$13*业态参数!$N$13*业态参数!$O$13) | J13: =IF('06人流模型'!H6<=0,0,业态参数!$M$13*业态参数!$N$13*业态参数!$O$13) | K13: =IF('06人流模型'!I6<=0,0,业态参数!$M$13*业态参数!$N$13*业态参数!$O$13) | ... U13: =IF('06人流模型'!S6<=0,0,业态参数!$M$13*业态参数!$N$13*业态参数!$O$13) | V13: =IF($F$35=0,0,F13/$F$35)
A14: 10 | B14: 婚礼花园 | C14: 自营 | D14: =IF('06人流模型'!B6<=0,0,业态参数!$M$14*业态参数!$N$14*业态参数!$O$14) | E14: =IF('06人流模型'!C6<=0,0,业态参数!$M$14*业态参数!$N$14*业态参数!$O$14) | F14: =IF('06人流模型'!D6<=0,0,业态参数!$M$14*业态参数!$N$14*业态参数!$O$14) | G14: =IF('06人流模型'!E6<=0,0,业态参数!$M$14*业态参数!$N$14*业态参数!$O$14) | H14: =IF('06人流模型'!F6<=0,0,业态参数!$M$14*业态参数!$N$14*业态参数!$O$14) | I14: =IF('06人流模型'!G6<=0,0,业态参数!$M$14*业态参数!$N$14*业态参数!$O$14) | J14: =IF('06人流模型'!H6<=0,0,业态参数!$M$14*业态参数!$N$14*业态参数!$O$14) | K14: =IF('06人流模型'!I6<=0,0,业态参数!$M$14*业态参数!$N$14*业态参数!$O$14) | ... U14: =IF('06人流模型'!S6<=0,0,业态参数!$M$14*业态参数!$N$14*业态参数!$O$14) | V14: =IF($F$35=0,0,F14/$F$35)
A15: 11 | B15: 雪地冰屋 | C15: 出租 | D15: =IF('06人流模型'!B6<=0,0,业态参数!$P$15*'06人流模型'!B6/75) | E15: =IF('06人流模型'!C6<=0,0,业态参数!$P$15*'06人流模型'!C6/75) | F15: =IF('06人流模型'!D6<=0,0,业态参数!$P$15*'06人流模型'!D6/75) | G15: =IF('06人流模型'!E6<=0,0,业态参数!$P$15*'06人流模型'!E6/75) | H15: =IF('06人流模型'!F6<=0,0,业态参数!$P$15*'06人流模型'!F6/75) | I15: =IF('06人流模型'!G6<=0,0,业态参数!$P$15*'06人流模型'!G6/75) | J15: =IF('06人流模型'!H6<=0,0,业态参数!$P$15*'06人流模型'!H6/75) | K15: =IF('06人流模型'!I6<=0,0,业态参数!$P$15*'06人流模型'!I6/75) | ... U15: =IF('06人流模型'!S6<=0,0,业态参数!$P$15*'06人流模型'!S6/75) | V15: =IF($F$35=0,0,F15/$F$35)
A16: 12 | B16: 森林剧场 | C16: 联营 | D16: =IF('06人流模型'!B6<=0,0,'06人流模型'!B6*业态参数!$G$16*业态参数!$H$16*业态参数!$F$16) | E16: =IF('06人流模型'!C6<=0,0,'06人流模型'!C6*业态参数!$G$16*业态参数!$H$16*业态参数!$F$16) | F16: =IF('06人流模型'!D6<=0,0,'06人流模型'!D6*业态参数!$G$16*业态参数!$H$16*业态参数!$F$16) | G16: =IF('06人流模型'!E6<=0,0,'06人流模型'!E6*业态参数!$G$16*业态参数!$H$16*业态参数!$F$16) | H16: =IF('06人流模型'!F6<=0,0,'06人流模型'!F6*业态参数!$G$16*业态参数!$H$16*业态参数!$F$16) | I16: =IF('06人流模型'!G6<=0,0,'06人流模型'!G6*业态参数!$G$16*业态参数!$H$16*业态参数!$F$16) | J16: =IF('06人流模型'!H6<=0,0,'06人流模型'!H6*业态参数!$G$16*业态参数!$H$16*业态参数!$F$16) | K16: =IF('06人流模型'!I6<=0,0,'06人流模型'!I6*业态参数!$G$16*业态参数!$H$16*业态参数!$F$16) | ... U16: =IF('06人流模型'!S6<=0,0,'06人流模型'!S6*业态参数!$G$16*业态参数!$H$16*业态参数!$F$16) | V16: =IF($F$35=0,0,F16/$F$35)
A17: 13 | B17: 禅修道苑 | C17: 联营 | D17: =IF('06人流模型'!B6<=0,0,'06人流模型'!B6*业态参数!$G$17*业态参数!$H$17*业态参数!$F$17) | E17: =IF('06人流模型'!C6<=0,0,'06人流模型'!C6*业态参数!$G$17*业态参数!$H$17*业态参数!$F$17) | F17: =IF('06人流模型'!D6<=0,0,'06人流模型'!D6*业态参数!$G$17*业态参数!$H$17*业态参数!$F$17) | G17: =IF('06人流模型'!E6<=0,0,'06人流模型'!E6*业态参数!$G$17*业态参数!$H$17*业态参数!$F$17) | H17: =IF('06人流模型'!F6<=0,0,'06人流模型'!F6*业态参数!$G$17*业态参数!$H$17*业态参数!$F$17) | I17: =IF('06人流模型'!G6<=0,0,'06人流模型'!G6*业态参数!$G$17*业态参数!$H$17*业态参数!$F$17) | J17: =IF('06人流模型'!H6<=0,0,'06人流模型'!H6*业态参数!$G$17*业态参数!$H$17*业态参数!$F$17) | K17: =IF('06人流模型'!I6<=0,0,'06人流模型'!I6*业态参数!$G$17*业态参数!$H$17*业态参数!$F$17) | ... U17: =IF('06人流模型'!S6<=0,0,'06人流模型'!S6*业态参数!$G$17*业态参数!$H$17*业态参数!$F$17) | V17: =IF($F$35=0,0,F17/$F$35)
A18: 14 | B18: 悬崖咖啡 | C18: 联营 | D18: =IF('06人流模型'!B6<=0,0,'06人流模型'!B6*业态参数!$G$18*业态参数!$H$18*业态参数!$F$18) | E18: =IF('06人流模型'!C6<=0,0,'06人流模型'!C6*业态参数!$G$18*业态参数!$H$18*业态参数!$F$18) | F18: =IF('06人流模型'!D6<=0,0,'06人流模型'!D6*业态参数!$G$18*业态参数!$H$18*业态参数!$F$18) | G18: =IF('06人流模型'!E6<=0,0,'06人流模型'!E6*业态参数!$G$18*业态参数!$H$18*业态参数!$F$18) | H18: =IF('06人流模型'!F6<=0,0,'06人流模型'!F6*业态参数!$G$18*业态参数!$H$18*业态参数!$F$18) | I18: =IF('06人流模型'!G6<=0,0,'06人流模型'!G6*业态参数!$G$18*业态参数!$H$18*业态参数!$F$18) | J18: =IF('06人流模型'!H6<=0,0,'06人流模型'!H6*业态参数!$G$18*业态参数!$H$18*业态参数!$F$18) | K18: =IF('06人流模型'!I6<=0,0,'06人流模型'!I6*业态参数!$G$18*业态参数!$H$18*业态参数!$F$18) | ... U18: =IF('06人流模型'!S6<=0,0,'06人流模型'!S6*业态参数!$G$18*业态参数!$H$18*业态参数!$F$18) | V18: =IF($F$35=0,0,F18/$F$35)
A19: 15 | B19: 许愿祈福 | C19: 联营 | D19: =IF('06人流模型'!B6<=0,0,'06人流模型'!B6*业态参数!$G$19*业态参数!$H$19*业态参数!$F$19) | E19: =IF('06人流模型'!C6<=0,0,'06人流模型'!C6*业态参数!$G$19*业态参数!$H$19*业态参数!$F$19) | F19: =IF('06人流模型'!D6<=0,0,'06人流模型'!D6*业态参数!$G$19*业态参数!$H$19*业态参数!$F$19) | G19: =IF('06人流模型'!E6<=0,0,'06人流模型'!E6*业态参数!$G$19*业态参数!$H$19*业态参数!$F$19) | H19: =IF('06人流模型'!F6<=0,0,'06人流模型'!F6*业态参数!$G$19*业态参数!$H$19*业态参数!$F$19) | I19: =IF('06人流模型'!G6<=0,0,'06人流模型'!G6*业态参数!$G$19*业态参数!$H$19*业态参数!$F$19) | J19: =IF('06人流模型'!H6<=0,0,'06人流模型'!H6*业态参数!$G$19*业态参数!$H$19*业态参数!$F$19) | K19: =IF('06人流模型'!I6<=0,0,'06人流模型'!I6*业态参数!$G$19*业态参数!$H$19*业态参数!$F$19) | ... U19: =IF('06人流模型'!S6<=0,0,'06人流模型'!S6*业态参数!$G$19*业态参数!$H$19*业态参数!$F$19) | V19: =IF($F$35=0,0,F19/$F$35)
A20: 16 | B20: 树屋及星空露营 | C20: 联营 | D20: =IF('06人流模型'!B6<=0,0,'06人流模型'!B6*业态参数!$G$20*业态参数!$H$20*业态参数!$F$20) | E20: =IF('06人流模型'!C6<=0,0,'06人流模型'!C6*业态参数!$G$20*业态参数!$H$20*业态参数!$F$20) | F20: =IF('06人流模型'!D6<=0,0,'06人流模型'!D6*业态参数!$G$20*业态参数!$H$20*业态参数!$F$20) | G20: =IF('06人流模型'!E6<=0,0,'06人流模型'!E6*业态参数!$G$20*业态参数!$H$20*业态参数!$F$20) | H20: =IF('06人流模型'!F6<=0,0,'06人流模型'!F6*业态参数!$G$20*业态参数!$H$20*业态参数!$F$20) | I20: =IF('06人流模型'!G6<=0,0,'06人流模型'!G6*业态参数!$G$20*业态参数!$H$20*业态参数!$F$20) | J20: =IF('06人流模型'!H6<=0,0,'06人流模型'!H6*业态参数!$G$20*业态参数!$H$20*业态参数!$F$20) | K20: =IF('06人流模型'!I6<=0,0,'06人流模型'!I6*业态参数!$G$20*业态参数!$H$20*业态参数!$F$20) | ... U20: =IF('06人流模型'!S6<=0,0,'06人流模型'!S6*业态参数!$G$20*业态参数!$H$20*业态参数!$F$20) | V20: =IF($F$35=0,0,F20/$F$35)
A21: 17 | B21: 山洞酒庄 | C21: 自营 | D21: =IF('06人流模型'!B6<=0,0,'06人流模型'!B6*业态参数!$G$21*业态参数!$H$21*业态参数!$F$21) | E21: =IF('06人流模型'!C6<=0,0,'06人流模型'!C6*业态参数!$G$21*业态参数!$H$21*业态参数!$F$21) | F21: =IF('06人流模型'!D6<=0,0,'06人流模型'!D6*业态参数!$G$21*业态参数!$H$21*业态参数!$F$21) | G21: =IF('06人流模型'!E6<=0,0,'06人流模型'!E6*业态参数!$G$21*业态参数!$H$21*业态参数!$F$21) | H21: =IF('06人流模型'!F6<=0,0,'06人流模型'!F6*业态参数!$G$21*业态参数!$H$21*业态参数!$F$21) | I21: =IF('06人流模型'!G6<=0,0,'06人流模型'!G6*业态参数!$G$21*业态参数!$H$21*业态参数!$F$21) | J21: =IF('06人流模型'!H6<=0,0,'06人流模型'!H6*业态参数!$G$21*业态参数!$H$21*业态参数!$F$21) | K21: =IF('06人流模型'!I6<=0,0,'06人流模型'!I6*业态参数!$G$21*业态参数!$H$21*业态参数!$F$21) | ... U21: =IF('06人流模型'!S6<=0,0,'06人流模型'!S6*业态参数!$G$21*业态参数!$H$21*业态参数!$F$21) | V21: =IF($F$35=0,0,F21/$F$35)
A22: 18 | B22: 公园旅拍 | C22: 联营 | D22: =IF('06人流模型'!B6<=0,0,'06人流模型'!B6*业态参数!$G$22*业态参数!$H$22*业态参数!$F$22) | E22: =IF('06人流模型'!C6<=0,0,'06人流模型'!C6*业态参数!$G$22*业态参数!$H$22*业态参数!$F$22) | F22: =IF('06人流模型'!D6<=0,0,'06人流模型'!D6*业态参数!$G$22*业态参数!$H$22*业态参数!$F$22) | G22: =IF('06人流模型'!E6<=0,0,'06人流模型'!E6*业态参数!$G$22*业态参数!$H$22*业态参数!$F$22) | H22: =IF('06人流模型'!F6<=0,0,'06人流模型'!F6*业态参数!$G$22*业态参数!$H$22*业态参数!$F$22) | I22: =IF('06人流模型'!G6<=0,0,'06人流模型'!G6*业态参数!$G$22*业态参数!$H$22*业态参数!$F$22) | J22: =IF('06人流模型'!H6<=0,0,'06人流模型'!H6*业态参数!$G$22*业态参数!$H$22*业态参数!$F$22) | K22: =IF('06人流模型'!I6<=0,0,'06人流模型'!I6*业态参数!$G$22*业态参数!$H$22*业态参数!$F$22) | ... U22: =IF('06人流模型'!S6<=0,0,'06人流模型'!S6*业态参数!$G$22*业态参数!$H$22*业态参数!$F$22) | V22: =IF($F$35=0,0,F22/$F$35)
A23: 19 | B23: 园区交通 | C23: 自营 | D23: =IF('06人流模型'!B6<=0,0,'06人流模型'!B6*业态参数!$G$23*业态参数!$H$23*业态参数!$F$23) | E23: =IF('06人流模型'!C6<=0,0,'06人流模型'!C6*业态参数!$G$23*业态参数!$H$23*业态参数!$F$23) | F23: =IF('06人流模型'!D6<=0,0,'06人流模型'!D6*业态参数!$G$23*业态参数!$H$23*业态参数!$F$23) | G23: =IF('06人流模型'!E6<=0,0,'06人流模型'!E6*业态参数!$G$23*业态参数!$H$23*业态参数!$F$23) | H23: =IF('06人流模型'!F6<=0,0,'06人流模型'!F6*业态参数!$G$23*业态参数!$H$23*业态参数!$F$23) | I23: =IF('06人流模型'!G6<=0,0,'06人流模型'!G6*业态参数!$G$23*业态参数!$H$23*业态参数!$F$23) | J23: =IF('06人流模型'!H6<=0,0,'06人流模型'!H6*业态参数!$G$23*业态参数!$H$23*业态参数!$F$23) | K23: =IF('06人流模型'!I6<=0,0,'06人流模型'!I6*业态参数!$G$23*业态参数!$H$23*业态参数!$F$23) | ... U23: =IF('06人流模型'!S6<=0,0,'06人流模型'!S6*业态参数!$G$23*业态参数!$H$23*业态参数!$F$23) | V23: =IF($F$35=0,0,F23/$F$35)
A24: 20 | B24: 红色研学/VR展馆 | C24: 自营 | D24: =IF('06人流模型'!B6<=0,0,'06人流模型'!B6*业态参数!$G$24*业态参数!$H$24*业态参数!$F$24) | E24: =IF('06人流模型'!C6<=0,0,'06人流模型'!C6*业态参数!$G$24*业态参数!$H$24*业态参数!$F$24) | F24: =IF('06人流模型'!D6<=0,0,'06人流模型'!D6*业态参数!$G$24*业态参数!$H$24*业态参数!$F$24) | G24: =IF('06人流模型'!E6<=0,0,'06人流模型'!E6*业态参数!$G$24*业态参数!$H$24*业态参数!$F$24) | H24: =IF('06人流模型'!F6<=0,0,'06人流模型'!F6*业态参数!$G$24*业态参数!$H$24*业态参数!$F$24) | I24: =IF('06人流模型'!G6<=0,0,'06人流模型'!G6*业态参数!$G$24*业态参数!$H$24*业态参数!$F$24) | J24: =IF('06人流模型'!H6<=0,0,'06人流模型'!H6*业态参数!$G$24*业态参数!$H$24*业态参数!$F$24) | K24: =IF('06人流模型'!I6<=0,0,'06人流模型'!I6*业态参数!$G$24*业态参数!$H$24*业态参数!$F$24) | ... U24: =IF('06人流模型'!S6<=0,0,'06人流模型'!S6*业态参数!$G$24*业态参数!$H$24*业态参数!$F$24) | V24: =IF($F$35=0,0,F24/$F$35)
A25: 21 | B25: 夜游/主题灯光 | C25: 自营 | D25: =IF('06人流模型'!B6<=0,0,'06人流模型'!B6*业态参数!$G$25*业态参数!$H$25*业态参数!$F$25) | E25: =IF('06人流模型'!C6<=0,0,'06人流模型'!C6*业态参数!$G$25*业态参数!$H$25*业态参数!$F$25) | F25: =IF('06人流模型'!D6<=0,0,'06人流模型'!D6*业态参数!$G$25*业态参数!$H$25*业态参数!$F$25) | G25: =IF('06人流模型'!E6<=0,0,'06人流模型'!E6*业态参数!$G$25*业态参数!$H$25*业态参数!$F$25) | H25: =IF('06人流模型'!F6<=0,0,'06人流模型'!F6*业态参数!$G$25*业态参数!$H$25*业态参数!$F$25) | I25: =IF('06人流模型'!G6<=0,0,'06人流模型'!G6*业态参数!$G$25*业态参数!$H$25*业态参数!$F$25) | J25: =IF('06人流模型'!H6<=0,0,'06人流模型'!H6*业态参数!$G$25*业态参数!$H$25*业态参数!$F$25) | K25: =IF('06人流模型'!I6<=0,0,'06人流模型'!I6*业态参数!$G$25*业态参数!$H$25*业态参数!$F$25) | ... U25: =IF('06人流模型'!S6<=0,0,'06人流模型'!S6*业态参数!$G$25*业态参数!$H$25*业态参数!$F$25) | V25: =IF($F$35=0,0,F25/$F$35)
A26: 22 | B26: 室内高尔夫 | C26: 联营 | D26: =IF('06人流模型'!B6<=0,0,'06人流模型'!B6*业态参数!$G$26*业态参数!$H$26*业态参数!$F$26) | E26: =IF('06人流模型'!C6<=0,0,'06人流模型'!C6*业态参数!$G$26*业态参数!$H$26*业态参数!$F$26) | F26: =IF('06人流模型'!D6<=0,0,'06人流模型'!D6*业态参数!$G$26*业态参数!$H$26*业态参数!$F$26) | G26: =IF('06人流模型'!E6<=0,0,'06人流模型'!E6*业态参数!$G$26*业态参数!$H$26*业态参数!$F$26) | H26: =IF('06人流模型'!F6<=0,0,'06人流模型'!F6*业态参数!$G$26*业态参数!$H$26*业态参数!$F$26) | I26: =IF('06人流模型'!G6<=0,0,'06人流模型'!G6*业态参数!$G$26*业态参数!$H$26*业态参数!$F$26) | J26: =IF('06人流模型'!H6<=0,0,'06人流模型'!H6*业态参数!$G$26*业态参数!$H$26*业态参数!$F$26) | K26: =IF('06人流模型'!I6<=0,0,'06人流模型'!I6*业态参数!$G$26*业态参数!$H$26*业态参数!$F$26) | ... U26: =IF('06人流模型'!S6<=0,0,'06人流模型'!S6*业态参数!$G$26*业态参数!$H$26*业态参数!$F$26) | V26: =IF($F$35=0,0,F26/$F$35)
A27: 23 | B27: 花海摄影 | C27: 自营 | D27: =IF('06人流模型'!B6<=0,0,'06人流模型'!B6*业态参数!$G$27*业态参数!$H$27*业态参数!$F$27) | E27: =IF('06人流模型'!C6<=0,0,'06人流模型'!C6*业态参数!$G$27*业态参数!$H$27*业态参数!$F$27) | F27: =IF('06人流模型'!D6<=0,0,'06人流模型'!D6*业态参数!$G$27*业态参数!$H$27*业态参数!$F$27) | G27: =IF('06人流模型'!E6<=0,0,'06人流模型'!E6*业态参数!$G$27*业态参数!$H$27*业态参数!$F$27) | H27: =IF('06人流模型'!F6<=0,0,'06人流模型'!F6*业态参数!$G$27*业态参数!$H$27*业态参数!$F$27) | I27: =IF('06人流模型'!G6<=0,0,'06人流模型'!G6*业态参数!$G$27*业态参数!$H$27*业态参数!$F$27) | J27: =IF('06人流模型'!H6<=0,0,'06人流模型'!H6*业态参数!$G$27*业态参数!$H$27*业态参数!$F$27) | K27: =IF('06人流模型'!I6<=0,0,'06人流模型'!I6*业态参数!$G$27*业态参数!$H$27*业态参数!$F$27) | ... U27: =IF('06人流模型'!S6<=0,0,'06人流模型'!S6*业态参数!$G$27*业态参数!$H$27*业态参数!$F$27) | V27: =IF($F$35=0,0,F27/$F$35)
A28: 24 | B28: 冬季抗联及戏雪 | C28: 联营 | D28: =IF('06人流模型'!B6<=0,0,'06人流模型'!B6*业态参数!$G$28*业态参数!$H$28*业态参数!$F$28) | E28: =IF('06人流模型'!C6<=0,0,'06人流模型'!C6*业态参数!$G$28*业态参数!$H$28*业态参数!$F$28) | F28: =IF('06人流模型'!D6<=0,0,'06人流模型'!D6*业态参数!$G$28*业态参数!$H$28*业态参数!$F$28) | G28: =IF('06人流模型'!E6<=0,0,'06人流模型'!E6*业态参数!$G$28*业态参数!$H$28*业态参数!$F$28) | H28: =IF('06人流模型'!F6<=0,0,'06人流模型'!F6*业态参数!$G$28*业态参数!$H$28*业态参数!$F$28) | I28: =IF('06人流模型'!G6<=0,0,'06人流模型'!G6*业态参数!$G$28*业态参数!$H$28*业态参数!$F$28) | J28: =IF('06人流模型'!H6<=0,0,'06人流模型'!H6*业态参数!$G$28*业态参数!$H$28*业态参数!$F$28) | K28: =IF('06人流模型'!I6<=0,0,'06人流模型'!I6*业态参数!$G$28*业态参数!$H$28*业态参数!$F$28) | ... U28: =IF('06人流模型'!S6<=0,0,'06人流模型'!S6*业态参数!$G$28*业态参数!$H$28*业态参数!$F$28) | V28: =IF($F$35=0,0,F28/$F$35)
A29: 25 | B29: 动物零食售卖 | C29: 自营 | D29: =IF('06人流模型'!B6<=0,0,'06人流模型'!B6*业态参数!$G$29*业态参数!$H$29*业态参数!$F$29) | E29: =IF('06人流模型'!C6<=0,0,'06人流模型'!C6*业态参数!$G$29*业态参数!$H$29*业态参数!$F$29) | F29: =IF('06人流模型'!D6<=0,0,'06人流模型'!D6*业态参数!$G$29*业态参数!$H$29*业态参数!$F$29) | G29: =IF('06人流模型'!E6<=0,0,'06人流模型'!E6*业态参数!$G$29*业态参数!$H$29*业态参数!$F$29) | H29: =IF('06人流模型'!F6<=0,0,'06人流模型'!F6*业态参数!$G$29*业态参数!$H$29*业态参数!$F$29) | I29: =IF('06人流模型'!G6<=0,0,'06人流模型'!G6*业态参数!$G$29*业态参数!$H$29*业态参数!$F$29) | J29: =IF('06人流模型'!H6<=0,0,'06人流模型'!H6*业态参数!$G$29*业态参数!$H$29*业态参数!$F$29) | K29: =IF('06人流模型'!I6<=0,0,'06人流模型'!I6*业态参数!$G$29*业态参数!$H$29*业态参数!$F$29) | ... U29: =IF('06人流模型'!S6<=0,0,'06人流模型'!S6*业态参数!$G$29*业态参数!$H$29*业态参数!$F$29) | V29: =IF($F$35=0,0,F29/$F$35)
A30: 26 | B30: 南入口停车场 | C30: 自营 | D30: =IF('06人流模型'!B6<=0,0,业态参数!$P$30*'06人流模型'!B6/75) | E30: =IF('06人流模型'!C6<=0,0,业态参数!$P$30*'06人流模型'!C6/75) | F30: =IF('06人流模型'!D6<=0,0,业态参数!$P$30*'06人流模型'!D6/75) | G30: =IF('06人流模型'!E6<=0,0,业态参数!$P$30*'06人流模型'!E6/75) | H30: =IF('06人流模型'!F6<=0,0,业态参数!$P$30*'06人流模型'!F6/75) | I30: =IF('06人流模型'!G6<=0,0,业态参数!$P$30*'06人流模型'!G6/75) | J30: =IF('06人流模型'!H6<=0,0,业态参数!$P$30*'06人流模型'!H6/75) | K30: =IF('06人流模型'!I6<=0,0,业态参数!$P$30*'06人流模型'!I6/75) | ... U30: =IF('06人流模型'!S6<=0,0,业态参数!$P$30*'06人流模型'!S6/75) | V30: =IF($F$35=0,0,F30/$F$35)
A31: 27 | B31: 健身区档期出租 | C31: 出租 | D31: =IF('06人流模型'!B6<=0,0,业态参数!$P$31*'06人流模型'!B6/75) | E31: =IF('06人流模型'!C6<=0,0,业态参数!$P$31*'06人流模型'!C6/75) | F31: =IF('06人流模型'!D6<=0,0,业态参数!$P$31*'06人流模型'!D6/75) | G31: =IF('06人流模型'!E6<=0,0,业态参数!$P$31*'06人流模型'!E6/75) | H31: =IF('06人流模型'!F6<=0,0,业态参数!$P$31*'06人流模型'!F6/75) | I31: =IF('06人流模型'!G6<=0,0,业态参数!$P$31*'06人流模型'!G6/75) | J31: =IF('06人流模型'!H6<=0,0,业态参数!$P$31*'06人流模型'!H6/75) | K31: =IF('06人流模型'!I6<=0,0,业态参数!$P$31*'06人流模型'!I6/75) | ... U31: =IF('06人流模型'!S6<=0,0,业态参数!$P$31*'06人流模型'!S6/75) | V31: =IF($F$35=0,0,F31/$F$35)
A32: 28 | B32: 林学科普衍生品 | C32: 自营 | D32: =IF('06人流模型'!B6<=0,0,'06人流模型'!B6*业态参数!$G$32*业态参数!$H$32*业态参数!$F$32) | E32: =IF('06人流模型'!C6<=0,0,'06人流模型'!C6*业态参数!$G$32*业态参数!$H$32*业态参数!$F$32) | F32: =IF('06人流模型'!D6<=0,0,'06人流模型'!D6*业态参数!$G$32*业态参数!$H$32*业态参数!$F$32) | G32: =IF('06人流模型'!E6<=0,0,'06人流模型'!E6*业态参数!$G$32*业态参数!$H$32*业态参数!$F$32) | H32: =IF('06人流模型'!F6<=0,0,'06人流模型'!F6*业态参数!$G$32*业态参数!$H$32*业态参数!$F$32) | I32: =IF('06人流模型'!G6<=0,0,'06人流模型'!G6*业态参数!$G$32*业态参数!$H$32*业态参数!$F$32) | J32: =IF('06人流模型'!H6<=0,0,'06人流模型'!H6*业态参数!$G$32*业态参数!$H$32*业态参数!$F$32) | K32: =IF('06人流模型'!I6<=0,0,'06人流模型'!I6*业态参数!$G$32*业态参数!$H$32*业态参数!$F$32) | ... U32: =IF('06人流模型'!S6<=0,0,'06人流模型'!S6*业态参数!$G$32*业态参数!$H$32*业态参数!$F$32) | V32: =IF($F$35=0,0,F32/$F$35)
A33: 29 | B33: 茶屋氧吧销售分成 | C33: 联营 | D33: =IF('06人流模型'!B6<=0,0,'06人流模型'!B6*业态参数!$G$33*业态参数!$H$33*业态参数!$F$33) | E33: =IF('06人流模型'!C6<=0,0,'06人流模型'!C6*业态参数!$G$33*业态参数!$H$33*业态参数!$F$33) | F33: =IF('06人流模型'!D6<=0,0,'06人流模型'!D6*业态参数!$G$33*业态参数!$H$33*业态参数!$F$33) | G33: =IF('06人流模型'!E6<=0,0,'06人流模型'!E6*业态参数!$G$33*业态参数!$H$33*业态参数!$F$33) | H33: =IF('06人流模型'!F6<=0,0,'06人流模型'!F6*业态参数!$G$33*业态参数!$H$33*业态参数!$F$33) | I33: =IF('06人流模型'!G6<=0,0,'06人流模型'!G6*业态参数!$G$33*业态参数!$H$33*业态参数!$F$33) | J33: =IF('06人流模型'!H6<=0,0,'06人流模型'!H6*业态参数!$G$33*业态参数!$H$33*业态参数!$F$33) | K33: =IF('06人流模型'!I6<=0,0,'06人流模型'!I6*业态参数!$G$33*业态参数!$H$33*业态参数!$F$33) | ... U33: =IF('06人流模型'!S6<=0,0,'06人流模型'!S6*业态参数!$G$33*业态参数!$H$33*业态参数!$F$33) | V33: =IF($F$35=0,0,F33/$F$35)
A34: 30 | B34: 栈道观景打卡 | C34: 自营 | D34: =IF('06人流模型'!B6<=0,0,'06人流模型'!B6*业态参数!$G$34*业态参数!$H$34*业态参数!$F$34) | E34: =IF('06人流模型'!C6<=0,0,'06人流模型'!C6*业态参数!$G$34*业态参数!$H$34*业态参数!$F$34) | F34: =IF('06人流模型'!D6<=0,0,'06人流模型'!D6*业态参数!$G$34*业态参数!$H$34*业态参数!$F$34) | G34: =IF('06人流模型'!E6<=0,0,'06人流模型'!E6*业态参数!$G$34*业态参数!$H$34*业态参数!$F$34) | H34: =IF('06人流模型'!F6<=0,0,'06人流模型'!F6*业态参数!$G$34*业态参数!$H$34*业态参数!$F$34) | I34: =IF('06人流模型'!G6<=0,0,'06人流模型'!G6*业态参数!$G$34*业态参数!$H$34*业态参数!$F$34) | J34: =IF('06人流模型'!H6<=0,0,'06人流模型'!H6*业态参数!$G$34*业态参数!$H$34*业态参数!$F$34) | K34: =IF('06人流模型'!I6<=0,0,'06人流模型'!I6*业态参数!$G$34*业态参数!$H$34*业态参数!$F$34) | ... U34: =IF('06人流模型'!S6<=0,0,'06人流模型'!S6*业态参数!$G$34*业态参数!$H$34*业态参数!$F$34) | V34: =IF($F$35=0,0,F34/$F$35)
B35: 公园账面收入合计 | D35: =SUM(D5:D34) | E35: =SUM(E5:E34) | F35: =SUM(F5:F34) | G35: =SUM(G5:G34) | H35: =SUM(H5:H34) | I35: =SUM(I5:I34) | J35: =SUM(J5:J34) | K35: =SUM(K5:K34) | ... V35: =SUM(V5:V34)
B36: 联营收入小计 | C36: 联营 | D36: =SUMIF($C$5:$C$34,C36,D5:D34) | E36: =SUMIF($C$5:$C$34,C36,E5:E34) | F36: =SUMIF($C$5:$C$34,C36,F5:F34) | G36: =SUMIF($C$5:$C$34,C36,G5:G34) | H36: =SUMIF($C$5:$C$34,C36,H5:H34) | I36: =SUMIF($C$5:$C$34,C36,I5:I34) | J36: =SUMIF($C$5:$C$34,C36,J5:J34) | K36: =SUMIF($C$5:$C$34,C36,K5:K34) | L36: =SUMIF($C$5:$C$34,C36,L5:L34) | M36: =SUMIF($C$5:$C$34,C36,M5:M34) | N36: =SUMIF($C$5:$C$34,C36,N5:N34) | O36: =SUMIF($C$5:$C$34,C36,O5:O34) | P36: =SUMIF($C$5:$C$34,C36,P5:P34) | Q36: =SUMIF($C$5:$C$34,C36,Q5:Q34) | R36: =SUMIF($C$5:$C$34,C36,R5:R34) | S36: =SUMIF($C$5:$C$34,C36,S5:S34) | T36: =SUMIF($C$5:$C$34,C36,T5:T34) | U36: =SUMIF($C$5:$C$34,C36,U5:U34)
B37: 自营收入小计 | C37: 自营 | D37: =SUMIF($C$5:$C$34,C37,D5:D34) | E37: =SUMIF($C$5:$C$34,C37,E5:E34) | F37: =SUMIF($C$5:$C$34,C37,F5:F34) | G37: =SUMIF($C$5:$C$34,C37,G5:G34) | H37: =SUMIF($C$5:$C$34,C37,H5:H34) | I37: =SUMIF($C$5:$C$34,C37,I5:I34) | J37: =SUMIF($C$5:$C$34,C37,J5:J34) | K37: =SUMIF($C$5:$C$34,C37,K5:K34) | L37: =SUMIF($C$5:$C$34,C37,L5:L34) | M37: =SUMIF($C$5:$C$34,C37,M5:M34) | N37: =SUMIF($C$5:$C$34,C37,N5:N34) | O37: =SUMIF($C$5:$C$34,C37,O5:O34) | P37: =SUMIF($C$5:$C$34,C37,P5:P34) | Q37: =SUMIF($C$5:$C$34,C37,Q5:Q34) | R37: =SUMIF($C$5:$C$34,C37,R5:R34) | S37: =SUMIF($C$5:$C$34,C37,S5:S34) | T37: =SUMIF($C$5:$C$34,C37,T5:T34) | U37: =SUMIF($C$5:$C$34,C37,U5:U34)
B38: 出租收入小计 | C38: 出租 | D38: =SUMIF($C$5:$C$34,C38,D5:D34) | E38: =SUMIF($C$5:$C$34,C38,E5:E34) | F38: =SUMIF($C$5:$C$34,C38,F5:F34) | G38: =SUMIF($C$5:$C$34,C38,G5:G34) | H38: =SUMIF($C$5:$C$34,C38,H5:H34) | I38: =SUMIF($C$5:$C$34,C38,I5:I34) | J38: =SUMIF($C$5:$C$34,C38,J5:J34) | K38: =SUMIF($C$5:$C$34,C38,K5:K34) | L38: =SUMIF($C$5:$C$34,C38,L5:L34) | M38: =SUMIF($C$5:$C$34,C38,M5:M34) | N38: =SUMIF($C$5:$C$34,C38,N5:N34) | O38: =SUMIF($C$5:$C$34,C38,O5:O34) | P38: =SUMIF($C$5:$C$34,C38,P5:P34) | Q38: =SUMIF($C$5:$C$34,C38,Q5:Q34) | R38: =SUMIF($C$5:$C$34,C38,R5:R34) | S38: =SUMIF($C$5:$C$34,C38,S5:S34) | T38: =SUMIF($C$5:$C$34,C38,T5:T34) | U38: =SUMIF($C$5:$C$34,C38,U5:U34)
B39: 品牌加盟收入小计 | C39: 品牌加盟 | D39: =SUMIF($C$5:$C$34,C39,D5:D34) | E39: =SUMIF($C$5:$C$34,C39,E5:E34) | F39: =SUMIF($C$5:$C$34,C39,F5:F34) | G39: =SUMIF($C$5:$C$34,C39,G5:G34) | H39: =SUMIF($C$5:$C$34,C39,H5:H34) | I39: =SUMIF($C$5:$C$34,C39,I5:I34) | J39: =SUMIF($C$5:$C$34,C39,J5:J34) | K39: =SUMIF($C$5:$C$34,C39,K5:K34) | L39: =SUMIF($C$5:$C$34,C39,L5:L34) | M39: =SUMIF($C$5:$C$34,C39,M5:M34) | N39: =SUMIF($C$5:$C$34,C39,N5:N34) | O39: =SUMIF($C$5:$C$34,C39,O5:O34) | P39: =SUMIF($C$5:$C$34,C39,P5:P34) | Q39: =SUMIF($C$5:$C$34,C39,Q5:Q34) | R39: =SUMIF($C$5:$C$34,C39,R5:R34) | S39: =SUMIF($C$5:$C$34,C39,S5:S34) | T39: =SUMIF($C$5:$C$34,C39,T5:T34) | U39: =SUMIF($C$5:$C$34,C39,U5:U34)
B41: 游客消费总额（表6校验） | D41: ='06人流模型'!B9 | E41: ='06人流模型'!C9 | F41: ='06人流模型'!D9 | G41: ='06人流模型'!E9 | H41: ='06人流模型'!F9 | I41: ='06人流模型'!G9 | J41: ='06人流模型'!H9 | K41: ='06人流模型'!I9 | ... U41: ='06人流模型'!S9
...

Sheet 宝贝王明细
A1: 超级宝贝王｜品牌加盟收入与成本（万元）
A2: 通化玉皇山公园｜以评估公司概算表5改造投资、表6人流模型为基准｜建设期2年｜经营期第3–18年
A4: 测算项 | B4: 第1年 | C4: 第2年 | D4: 第3年 | E4: 第4年 | F4: 第5年 | G4: 第6年 | H4: 第7年 | I4: 第8年 | J4: 第9年 | K4: 第10年 | L4: 第11年 | M4: 第12年 | N4: 第13年 | O4: 第14年 | P4: 第15年 | Q4: 第16年 | R4: 第17年 | S4: 第18年
A5: 全园人次（万人） | B5: ='06人流模型'!B6 | C5: ='06人流模型'!C6 | D5: ='06人流模型'!D6 | E5: ='06人流模型'!E6 | F5: ='06人流模型'!F6 | G5: ='06人流模型'!G6 | H5: ='06人流模型'!H6 | I5: ='06人流模型'!I6 | ... S5: ='06人流模型'!S6
A6: 研学客流（万人） | B6: =IF(B5<=0,0,MIN(20,B5*业态参数!$B$38)) | C6: =IF(C5<=0,0,MIN(20,C5*业态参数!$B$38)) | D6: =IF(D5<=0,0,MIN(20,D5*业态参数!$B$38)) | E6: =IF(E5<=0,0,MIN(20,E5*业态参数!$B$38)) | F6: =IF(F5<=0,0,MIN(20,F5*业态参数!$B$38)) | G6: =IF(G5<=0,0,MIN(20,G5*业态参数!$B$38)) | H6: =IF(H5<=0,0,MIN(20,H5*业态参数!$B$38)) | I6: =IF(I5<=0,0,MIN(20,I5*业态参数!$B$38)) | ... S6: =IF(S5<=0,0,MIN(20,S5*业态参数!$B$38))
A7: 一般客流（万人） | B7: =IF(B5<=0,0,MIN(20,B5*业态参数!$B$39)) | C7: =IF(C5<=0,0,MIN(20,C5*业态参数!$B$39)) | D7: =IF(D5<=0,0,MIN(20,D5*业态参数!$B$39)) | E7: =IF(E5<=0,0,MIN(20,E5*业态参数!$B$39)) | F7: =IF(F5<=0,0,MIN(20,F5*业态参数!$B$39)) | G7: =IF(G5<=0,0,MIN(20,G5*业态参数!$B$39)) | H7: =IF(H5<=0,0,MIN(20,H5*业态参数!$B$39)) | I7: =IF(I5<=0,0,MIN(20,I5*业态参数!$B$39)) | ... S7: =IF(S5<=0,0,MIN(20,S5*业态参数!$B$39))
A8: 总接待（万人） | B8: =B6+B7 | C8: =C6+C7 | D8: =D6+D7 | E8: =E6+E7 | F8: =F6+F7 | G8: =G6+G7 | H8: =H6+H7 | I8: =I6+I7 | ... S8: =S6+S7
A9: 研学收入 | B9: =B6*业态参数!$B$40 | C9: =C6*业态参数!$B$40 | D9: =D6*业态参数!$B$40 | E9: =E6*业态参数!$B$40 | F9: =F6*业态参数!$B$40 | G9: =G6*业态参数!$B$40 | H9: =H6*业态参数!$B$40 | I9: =I6*业态参数!$B$40 | ... S9: =S6*业态参数!$B$40
A10: 一般客流收入 | B10: =B7*业态参数!$B$41 | C10: =C7*业态参数!$B$41 | D10: =D7*业态参数!$B$41 | E10: =E7*业态参数!$B$41 | F10: =F7*业态参数!$B$41 | G10: =G7*业态参数!$B$41 | H10: =H7*业态参数!$B$41 | I10: =I7*业态参数!$B$41 | ... S10: =S7*业态参数!$B$41
A11: 门票/体验流水 | B11: =B9+B10 | C11: =C9+C10 | D11: =D9+D10 | E11: =E9+E10 | F11: =F9+F10 | G11: =G9+G10 | H11: =H9+H10 | I11: =I9+I10 | ... S11: =S9+S10
A12: 二消收入 | B12: =B8*业态参数!$B$42*业态参数!$B$43 | C12: =C8*业态参数!$B$42*业态参数!$B$43 | D12: =D8*业态参数!$B$42*业态参数!$B$43 | E12: =E8*业态参数!$B$42*业态参数!$B$43 | F12: =F8*业态参数!$B$42*业态参数!$B$43 | G12: =G8*业态参数!$B$42*业态参数!$B$43 | H12: =H8*业态参数!$B$42*业态参数!$B$43 | I12: =I8*业态参数!$B$42*业态参数!$B$43 | ... S12: =S8*业态参数!$B$42*业态参数!$B$43
A13: 万达门票分成10% | B13: =B11*业态参数!$B$44 | C13: =C11*业态参数!$B$44 | D13: =D11*业态参数!$B$44 | E13: =E11*业态参数!$B$44 | F13: =F11*业态参数!$B$44 | G13: =G11*业态参数!$B$44 | H13: =H11*业态参数!$B$44 | I13: =I11*业态参数!$B$44 | ... S13: =S11*业态参数!$B$44
A14: 线上渠道佣金 | B14: =B10*业态参数!$B$45*业态参数!$B$46 | C14: =C10*业态参数!$B$45*业态参数!$B$46 | D14: =D10*业态参数!$B$45*业态参数!$B$46 | E14: =E10*业态参数!$B$45*业态参数!$B$46 | F14: =F10*业态参数!$B$45*业态参数!$B$46 | G14: =G10*业态参数!$B$45*业态参数!$B$46 | H14: =H10*业态参数!$B$45*业态参数!$B$46 | I14: =I10*业态参数!$B$45*业态参数!$B$46 | ... S14: =S10*业态参数!$B$45*业态参数!$B$46
A15: 销售提成 | B15: =B16*业态参数!$B$47 | C15: =C16*业态参数!$B$47 | D15: =D16*业态参数!$B$47 | E15: =E16*业态参数!$B$47 | F15: =F16*业态参数!$B$47 | G15: =G16*业态参数!$B$47 | H15: =H16*业态参数!$B$47 | I15: =I16*业态参数!$B$47 | ... S15: =S16*业态参数!$B$47
A16: 营业收入合计 | B16: =B11+B12 | C16: =C11+C12 | D16: =D11+D12 | E16: =E11+E12 | F16: =F11+F12 | G16: =G11+G12 | H16: =H11+H12 | I16: =I11+I12 | ... S16: =S11+S12
A17: 游乐维护 | B17: =B11*业态参数!$B$48 | C17: =C11*业态参数!$B$48 | D17: =D11*业态参数!$B$48 | E17: =E11*业态参数!$B$48 | F17: =F11*业态参数!$B$48 | G17: =G11*业态参数!$B$48 | H17: =H11*业态参数!$B$48 | I17: =I11*业态参数!$B$48 | ... S17: =S11*业态参数!$B$48
A18: 二消商品成本 | B18: =B12*业态参数!$B$49 | C18: =C12*业态参数!$B$49 | D18: =D12*业态参数!$B$49 | E18: =E12*业态参数!$B$49 | F18: =F12*业态参数!$B$49 | G18: =G12*业态参数!$B$49 | H18: =H12*业态参数!$B$49 | I18: =I12*业态参数!$B$49 | ... S18: =S12*业态参数!$B$49
A19: 日常营销 | B19: =B11*业态参数!$B$50 | C19: =C11*业态参数!$B$50 | D19: =D11*业态参数!$B$50 | E19: =E11*业态参数!$B$50 | F19: =F11*业态参数!$B$50 | G19: =G11*业态参数!$B$50 | H19: =H11*业态参数!$B$50 | I19: =I11*业态参数!$B$50 | ... S19: =S11*业态参数!$B$50
A20: 开业/年度专项 | B20: =IF(B5<=0,0,IF(B5>=70,8,12)) | C20: =IF(C5<=0,0,IF(C5>=70,8,12)) | D20: =IF(D5<=0,0,IF(D5>=70,8,12)) | E20: =IF(E5<=0,0,IF(E5>=70,8,12)) | F20: =IF(F5<=0,0,IF(F5>=70,8,12)) | G20: =IF(G5<=0,0,IF(G5>=70,8,12)) | H20: =IF(H5<=0,0,IF(H5>=70,8,12)) | I20: =IF(I5<=0,0,IF(I5>=70,8,12)) | ... S20: =IF(S5<=0,0,IF(S5>=70,8,12))
A21: 人工成本（26人） | B21: =IF(B5<=0,0,人力编制!B35) | C21: =IF(C5<=0,0,人力编制!B35) | D21: =IF(D5<=0,0,人力编制!B35) | E21: =IF(E5<=0,0,人力编制!B35) | F21: =IF(F5<=0,0,人力编制!B35) | G21: =IF(G5<=0,0,人力编制!B35) | H21: =IF(H5<=0,0,人力编制!B35) | I21: =IF(I5<=0,0,人力编制!B35) | J21: =IF(J5<=0,0,人力编制!B35) | K21: =IF(K5<=0,0,人力编制!B35) | L21: =IF(L5<=0,0,人力编制!B35) | M21: =IF(M5<=0,0,人力编制!B35) | N21: =IF(N5<=0,0,人力编制!B35) | O21: =IF(O5<=0,0,人力编制!B35) | P21: =IF(P5<=0,0,人力编制!B35) | Q21: =IF(Q5<=0,0,人力编制!B35) | R21: =IF(R5<=0,0,人力编制!B35) | S21: =IF(S5<=0,0,人力编制!B35)
A22: 水电能耗 | B22: =B8*业态参数!$B$51 | C22: =C8*业态参数!$B$51 | D22: =D8*业态参数!$B$51 | E22: =E8*业态参数!$B$51 | F22: =F8*业态参数!$B$51 | G22: =G8*业态参数!$B$51 | H22: =H8*业态参数!$B$51 | I22: =I8*业态参数!$B$51 | ... S22: =S8*业态参数!$B$51
A23: 保安保洁（项目内） | B23: =IF(B5<=0,0,业态参数!$B$52) | C23: =IF(C5<=0,0,业态参数!$B$52) | D23: =IF(D5<=0,0,业态参数!$B$52) | E23: =IF(E5<=0,0,业态参数!$B$52) | F23: =IF(F5<=0,0,业态参数!$B$52) | G23: =IF(G5<=0,0,业态参数!$B$52) | H23: =IF(H5<=0,0,业态参数!$B$52) | I23: =IF(I5<=0,0,业态参数!$B$52) | ... S23: =IF(S5<=0,0,业态参数!$B$52)
A24: 经营成本合计 | B24: =SUM(B13:B15,B17:B23) | C24: =SUM(C13:C15,C17:C23) | D24: =SUM(D13:D15,D17:D23) | E24: =SUM(E13:E15,E17:E23) | F24: =SUM(F13:F15,F17:F23) | G24: =SUM(G13:G15,G17:G23) | H24: =SUM(H13:H15,H17:H23) | I24: =SUM(I13:I15,I17:I23) | ... S24: =SUM(S13:S15,S17:S23)
A25: 经营贡献 | B25: =B16-B24 | C25: =C16-C24 | D25: =D16-D24 | E25: =E16-E24 | F25: =F16-F24 | G25: =G16-G24 | H25: =H16-H24 | I25: =I16-I24 | ... S25: =S16-S24
A27: 万达10%只计提门票/体验流水；品牌使用费100万元已包含在表5儿童乐园投资中，不再单独现金列支。设备折旧在全园折旧中统一计提，本表不再重复。

Sheet 成本利润
A1: 项目成本与经营贡献｜按经营性质区分构成（万元）
A2: 通化玉皇山公园｜以评估公司概算表5改造投资、表6人流模型为基准｜建设期2年｜经营期第3–18年
A3: 联营/出租：成本=收入×（直接+渠道+运营分摊），不含对方人工。自营：变动成本同左，编制工资在下方「自营及联营协助人力」一次计入。宝贝王成本取专项表。
A4: 序号 | B4: 经营项目 | C4: 经营性质 | D4: 第1年成本 | E4: 第2年成本 | F4: 第3年成本 | G4: 第4年成本 | H4: 第5年成本 | I4: 第6年成本 | J4: 第7年成本 | K4: 第8年成本 | L4: 第9年成本 | M4: 第10年成本 | N4: 第11年成本 | O4: 第12年成本 | P4: 第13年成本 | Q4: 第14年成本 | R4: 第15年成本 | S4: 第16年成本 | T4: 第17年成本 | U4: 第18年成本 | V4: 达产贡献率
A5: 1 | B5: 玉皇山大马戏 | C5: 联营 | D5: =收入测算!D5*(业态参数!$Q$5+业态参数!$R$5+业态参数!$S$5) | E5: =收入测算!E5*(业态参数!$Q$5+业态参数!$R$5+业态参数!$S$5) | F5: =收入测算!F5*(业态参数!$Q$5+业态参数!$R$5+业态参数!$S$5) | G5: =收入测算!G5*(业态参数!$Q$5+业态参数!$R$5+业态参数!$S$5) | H5: =收入测算!H5*(业态参数!$Q$5+业态参数!$R$5+业态参数!$S$5) | I5: =收入测算!I5*(业态参数!$Q$5+业态参数!$R$5+业态参数!$S$5) | J5: =收入测算!J5*(业态参数!$Q$5+业态参数!$R$5+业态参数!$S$5) | K5: =收入测算!K5*(业态参数!$Q$5+业态参数!$R$5+业态参数!$S$5) | ... U5: =收入测算!U5*(业态参数!$Q$5+业态参数!$R$5+业态参数!$S$5) | V5: =IF(收入测算!F5=0,0,(收入测算!F5-F5)/收入测算!F5)
A6: 2 | B6: 超级宝贝王 | C6: 品牌加盟 | D6: =宝贝王明细!B24 | E6: =宝贝王明细!C24 | F6: =宝贝王明细!D24 | G6: =宝贝王明细!E24 | H6: =宝贝王明细!F24 | I6: =宝贝王明细!G24 | J6: =宝贝王明细!H24 | K6: =宝贝王明细!I24 | ... U6: =宝贝王明细!S24 | V6: =IF(收入测算!F6=0,0,(收入测算!F6-F6)/收入测算!F6)
A7: 3 | B7: 土特产伴手礼 | C7: 自营 | D7: =收入测算!D7*(业态参数!$Q$7+业态参数!$R$7+业态参数!$S$7) | E7: =收入测算!E7*(业态参数!$Q$7+业态参数!$R$7+业态参数!$S$7) | F7: =收入测算!F7*(业态参数!$Q$7+业态参数!$R$7+业态参数!$S$7) | G7: =收入测算!G7*(业态参数!$Q$7+业态参数!$R$7+业态参数!$S$7) | H7: =收入测算!H7*(业态参数!$Q$7+业态参数!$R$7+业态参数!$S$7) | I7: =收入测算!I7*(业态参数!$Q$7+业态参数!$R$7+业态参数!$S$7) | J7: =收入测算!J7*(业态参数!$Q$7+业态参数!$R$7+业态参数!$S$7) | K7: =收入测算!K7*(业态参数!$Q$7+业态参数!$R$7+业态参数!$S$7) | ... U7: =收入测算!U7*(业态参数!$Q$7+业态参数!$R$7+业态参数!$S$7) | V7: =IF(收入测算!F7=0,0,(收入测算!F7-F7)/收入测算!F7)
A8: 4 | B8: 动物萌宠互动 | C8: 联营 | D8: =收入测算!D8*(业态参数!$Q$8+业态参数!$R$8+业态参数!$S$8) | E8: =收入测算!E8*(业态参数!$Q$8+业态参数!$R$8+业态参数!$S$8) | F8: =收入测算!F8*(业态参数!$Q$8+业态参数!$R$8+业态参数!$S$8) | G8: =收入测算!G8*(业态参数!$Q$8+业态参数!$R$8+业态参数!$S$8) | H8: =收入测算!H8*(业态参数!$Q$8+业态参数!$R$8+业态参数!$S$8) | I8: =收入测算!I8*(业态参数!$Q$8+业态参数!$R$8+业态参数!$S$8) | J8: =收入测算!J8*(业态参数!$Q$8+业态参数!$R$8+业态参数!$S$8) | K8: =收入测算!K8*(业态参数!$Q$8+业态参数!$R$8+业态参数!$S$8) | ... U8: =收入测算!U8*(业态参数!$Q$8+业态参数!$R$8+业态参数!$S$8) | V8: =IF(收入测算!F8=0,0,(收入测算!F8-F8)/收入测算!F8)
A9: 5 | B9: 湖畔影院 | C9: 联营 | D9: =收入测算!D9*(业态参数!$Q$9+业态参数!$R$9+业态参数!$S$9) | E9: =收入测算!E9*(业态参数!$Q$9+业态参数!$R$9+业态参数!$S$9) | F9: =收入测算!F9*(业态参数!$Q$9+业态参数!$R$9+业态参数!$S$9) | G9: =收入测算!G9*(业态参数!$Q$9+业态参数!$R$9+业态参数!$S$9) | H9: =收入测算!H9*(业态参数!$Q$9+业态参数!$R$9+业态参数!$S$9) | I9: =收入测算!I9*(业态参数!$Q$9+业态参数!$R$9+业态参数!$S$9) | J9: =收入测算!J9*(业态参数!$Q$9+业态参数!$R$9+业态参数!$S$9) | K9: =收入测算!K9*(业态参数!$Q$9+业态参数!$R$9+业态参数!$S$9) | ... U9: =收入测算!U9*(业态参数!$Q$9+业态参数!$R$9+业态参数!$S$9) | V9: =IF(收入测算!F9=0,0,(收入测算!F9-F9)/收入测算!F9)
A10: 6 | B10: 青年街区 | C10: 出租 | D10: =收入测算!D10*(业态参数!$Q$10+业态参数!$R$10+业态参数!$S$10) | E10: =收入测算!E10*(业态参数!$Q$10+业态参数!$R$10+业态参数!$S$10) | F10: =收入测算!F10*(业态参数!$Q$10+业态参数!$R$10+业态参数!$S$10) | G10: =收入测算!G10*(业态参数!$Q$10+业态参数!$R$10+业态参数!$S$10) | H10: =收入测算!H10*(业态参数!$Q$10+业态参数!$R$10+业态参数!$S$10) | I10: =收入测算!I10*(业态参数!$Q$10+业态参数!$R$10+业态参数!$S$10) | J10: =收入测算!J10*(业态参数!$Q$10+业态参数!$R$10+业态参数!$S$10) | K10: =收入测算!K10*(业态参数!$Q$10+业态参数!$R$10+业态参数!$S$10) | ... U10: =收入测算!U10*(业态参数!$Q$10+业态参数!$R$10+业态参数!$S$10) | V10: =IF(收入测算!F10=0,0,(收入测算!F10-F10)/收入测算!F10)
A11: 7 | B11: 茶屋氧吧 | C11: 联营 | D11: =收入测算!D11*(业态参数!$Q$11+业态参数!$R$11+业态参数!$S$11) | E11: =收入测算!E11*(业态参数!$Q$11+业态参数!$R$11+业态参数!$S$11) | F11: =收入测算!F11*(业态参数!$Q$11+业态参数!$R$11+业态参数!$S$11) | G11: =收入测算!G11*(业态参数!$Q$11+业态参数!$R$11+业态参数!$S$11) | H11: =收入测算!H11*(业态参数!$Q$11+业态参数!$R$11+业态参数!$S$11) | I11: =收入测算!I11*(业态参数!$Q$11+业态参数!$R$11+业态参数!$S$11) | J11: =收入测算!J11*(业态参数!$Q$11+业态参数!$R$11+业态参数!$S$11) | K11: =收入测算!K11*(业态参数!$Q$11+业态参数!$R$11+业态参数!$S$11) | ... U11: =收入测算!U11*(业态参数!$Q$11+业态参数!$R$11+业态参数!$S$11) | V11: =IF(收入测算!F11=0,0,(收入测算!F11-F11)/收入测算!F11)
A12: 8 | B12: 素食餐厅 | C12: 联营 | D12: =收入测算!D12*(业态参数!$Q$12+业态参数!$R$12+业态参数!$S$12) | E12: =收入测算!E12*(业态参数!$Q$12+业态参数!$R$12+业态参数!$S$12) | F12: =收入测算!F12*(业态参数!$Q$12+业态参数!$R$12+业态参数!$S$12) | G12: =收入测算!G12*(业态参数!$Q$12+业态参数!$R$12+业态参数!$S$12) | H12: =收入测算!H12*(业态参数!$Q$12+业态参数!$R$12+业态参数!$S$12) | I12: =收入测算!I12*(业态参数!$Q$12+业态参数!$R$12+业态参数!$S$12) | J12: =收入测算!J12*(业态参数!$Q$12+业态参数!$R$12+业态参数!$S$12) | K12: =收入测算!K12*(业态参数!$Q$12+业态参数!$R$12+业态参数!$S$12) | ... U12: =收入测算!U12*(业态参数!$Q$12+业态参数!$R$12+业态参数!$S$12) | V12: =IF(收入测算!F12=0,0,(收入测算!F12-F12)/收入测算!F12)
A13: 9 | B13: 庙会/市集 | C13: 联营 | D13: =收入测算!D13*(业态参数!$Q$13+业态参数!$R$13+业态参数!$S$13) | E13: =收入测算!E13*(业态参数!$Q$13+业态参数!$R$13+业态参数!$S$13) | F13: =收入测算!F13*(业态参数!$Q$13+业态参数!$R$13+业态参数!$S$13) | G13: =收入测算!G13*(业态参数!$Q$13+业态参数!$R$13+业态参数!$S$13) | H13: =收入测算!H13*(业态参数!$Q$13+业态参数!$R$13+业态参数!$S$13) | I13: =收入测算!I13*(业态参数!$Q$13+业态参数!$R$13+业态参数!$S$13) | J13: =收入测算!J13*(业态参数!$Q$13+业态参数!$R$13+业态参数!$S$13) | K13: =收入测算!K13*(业态参数!$Q$13+业态参数!$R$13+业态参数!$S$13) | ... U13: =收入测算!U13*(业态参数!$Q$13+业态参数!$R$13+业态参数!$S$13) | V13: =IF(收入测算!F13=0,0,(收入测算!F13-F13)/收入测算!F13)
A14: 10 | B14: 婚礼花园 | C14: 自营 | D14: =收入测算!D14*(业态参数!$Q$14+业态参数!$R$14+业态参数!$S$14) | E14: =收入测算!E14*(业态参数!$Q$14+业态参数!$R$14+业态参数!$S$14) | F14: =收入测算!F14*(业态参数!$Q$14+业态参数!$R$14+业态参数!$S$14) | G14: =收入测算!G14*(业态参数!$Q$14+业态参数!$R$14+业态参数!$S$14) | H14: =收入测算!H14*(业态参数!$Q$14+业态参数!$R$14+业态参数!$S$14) | I14: =收入测算!I14*(业态参数!$Q$14+业态参数!$R$14+业态参数!$S$14) | J14: =收入测算!J14*(业态参数!$Q$14+业态参数!$R$14+业态参数!$S$14) | K14: =收入测算!K14*(业态参数!$Q$14+业态参数!$R$14+业态参数!$S$14) | ... U14: =收入测算!U14*(业态参数!$Q$14+业态参数!$R$14+业态参数!$S$14) | V14: =IF(收入测算!F14=0,0,(收入测算!F14-F14)/收入测算!F14)
A15: 11 | B15: 雪地冰屋 | C15: 出租 | D15: =收入测算!D15*(业态参数!$Q$15+业态参数!$R$15+业态参数!$S$15) | E15: =收入测算!E15*(业态参数!$Q$15+业态参数!$R$15+业态参数!$S$15) | F15: =收入测算!F15*(业态参数!$Q$15+业态参数!$R$15+业态参数!$S$15) | G15: =收入测算!G15*(业态参数!$Q$15+业态参数!$R$15+业态参数!$S$15) | H15: =收入测算!H15*(业态参数!$Q$15+业态参数!$R$15+业态参数!$S$15) | I15: =收入测算!I15*(业态参数!$Q$15+业态参数!$R$15+业态参数!$S$15) | J15: =收入测算!J15*(业态参数!$Q$15+业态参数!$R$15+业态参数!$S$15) | K15: =收入测算!K15*(业态参数!$Q$15+业态参数!$R$15+业态参数!$S$15) | ... U15: =收入测算!U15*(业态参数!$Q$15+业态参数!$R$15+业态参数!$S$15) | V15: =IF(收入测算!F15=0,0,(收入测算!F15-F15)/收入测算!F15)
A16: 12 | B16: 森林剧场 | C16: 联营 | D16: =收入测算!D16*(业态参数!$Q$16+业态参数!$R$16+业态参数!$S$16) | E16: =收入测算!E16*(业态参数!$Q$16+业态参数!$R$16+业态参数!$S$16) | F16: =收入测算!F16*(业态参数!$Q$16+业态参数!$R$16+业态参数!$S$16) | G16: =收入测算!G16*(业态参数!$Q$16+业态参数!$R$16+业态参数!$S$16) | H16: =收入测算!H16*(业态参数!$Q$16+业态参数!$R$16+业态参数!$S$16) | I16: =收入测算!I16*(业态参数!$Q$16+业态参数!$R$16+业态参数!$S$16) | J16: =收入测算!J16*(业态参数!$Q$16+业态参数!$R$16+业态参数!$S$16) | K16: =收入测算!K16*(业态参数!$Q$16+业态参数!$R$16+业态参数!$S$16) | ... U16: =收入测算!U16*(业态参数!$Q$16+业态参数!$R$16+业态参数!$S$16) | V16: =IF(收入测算!F16=0,0,(收入测算!F16-F16)/收入测算!F16)
A17: 13 | B17: 禅修道苑 | C17: 联营 | D17: =收入测算!D17*(业态参数!$Q$17+业态参数!$R$17+业态参数!$S$17) | E17: =收入测算!E17*(业态参数!$Q$17+业态参数!$R$17+业态参数!$S$17) | F17: =收入测算!F17*(业态参数!$Q$17+业态参数!$R$17+业态参数!$S$17) | G17: =收入测算!G17*(业态参数!$Q$17+业态参数!$R$17+业态参数!$S$17) | H17: =收入测算!H17*(业态参数!$Q$17+业态参数!$R$17+业态参数!$S$17) | I17: =收入测算!I17*(业态参数!$Q$17+业态参数!$R$17+业态参数!$S$17) | J17: =收入测算!J17*(业态参数!$Q$17+业态参数!$R$17+业态参数!$S$17) | K17: =收入测算!K17*(业态参数!$Q$17+业态参数!$R$17+业态参数!$S$17) | ... U17: =收入测算!U17*(业态参数!$Q$17+业态参数!$R$17+业态参数!$S$17) | V17: =IF(收入测算!F17=0,0,(收入测算!F17-F17)/收入测算!F17)
A18: 14 | B18: 悬崖咖啡 | C18: 联营 | D18: =收入测算!D18*(业态参数!$Q$18+业态参数!$R$18+业态参数!$S$18) | E18: =收入测算!E18*(业态参数!$Q$18+业态参数!$R$18+业态参数!$S$18) | F18: =收入测算!F18*(业态参数!$Q$18+业态参数!$R$18+业态参数!$S$18) | G18: =收入测算!G18*(业态参数!$Q$18+业态参数!$R$18+业态参数!$S$18) | H18: =收入测算!H18*(业态参数!$Q$18+业态参数!$R$18+业态参数!$S$18) | I18: =收入测算!I18*(业态参数!$Q$18+业态参数!$R$18+业态参数!$S$18) | J18: =收入测算!J18*(业态参数!$Q$18+业态参数!$R$18+业态参数!$S$18) | K18: =收入测算!K18*(业态参数!$Q$18+业态参数!$R$18+业态参数!$S$18) | ... U18: =收入测算!U18*(业态参数!$Q$18+业态参数!$R$18+业态参数!$S$18) | V18: =IF(收入测算!F18=0,0,(收入测算!F18-F18)/收入测算!F18)
A19: 15 | B19: 许愿祈福 | C19: 联营 | D19: =收入测算!D19*(业态参数!$Q$19+业态参数!$R$19+业态参数!$S$19) | E19: =收入测算!E19*(业态参数!$Q$19+业态参数!$R$19+业态参数!$S$19) | F19: =收入测算!F19*(业态参数!$Q$19+业态参数!$R$19+业态参数!$S$19) | G19: =收入测算!G19*(业态参数!$Q$19+业态参数!$R$19+业态参数!$S$19) | H19: =收入测算!H19*(业态参数!$Q$19+业态参数!$R$19+业态参数!$S$19) | I19: =收入测算!I19*(业态参数!$Q$19+业态参数!$R$19+业态参数!$S$19) | J19: =收入测算!J19*(业态参数!$Q$19+业态参数!$R$19+业态参数!$S$19) | K19: =收入测算!K19*(业态参数!$Q$19+业态参数!$R$19+业态参数!$S$19) | ... U19: =收入测算!U19*(业态参数!$Q$19+业态参数!$R$19+业态参数!$S$19) | V19: =IF(收入测算!F19=0,0,(收入测算!F19-F19)/收入测算!F19)
A20: 16 | B20: 树屋及星空露营 | C20: 联营 | D20: =收入测算!D20*(业态参数!$Q$20+业态参数!$R$20+业态参数!$S$20) | E20: =收入测算!E20*(业态参数!$Q$20+业态参数!$R$20+业态参数!$S$20) | F20: =收入测算!F20*(业态参数!$Q$20+业态参数!$R$20+业态参数!$S$20) | G20: =收入测算!G20*(业态参数!$Q$20+业态参数!$R$20+业态参数!$S$20) | H20: =收入测算!H20*(业态参数!$Q$20+业态参数!$R$20+业态参数!$S$20) | I20: =收入测算!I20*(业态参数!$Q$20+业态参数!$R$20+业态参数!$S$20) | J20: =收入测算!J20*(业态参数!$Q$20+业态参数!$R$20+业态参数!$S$20) | K20: =收入测算!K20*(业态参数!$Q$20+业态参数!$R$20+业态参数!$S$20) | ... U20: =收入测算!U20*(业态参数!$Q$20+业态参数!$R$20+业态参数!$S$20) | V20: =IF(收入测算!F20=0,0,(收入测算!F20-F20)/收入测算!F20)
A21: 17 | B21: 山洞酒庄 | C21: 自营 | D21: =收入测算!D21*(业态参数!$Q$21+业态参数!$R$21+业态参数!$S$21) | E21: =收入测算!E21*(业态参数!$Q$21+业态参数!$R$21+业态参数!$S$21) | F21: =收入测算!F21*(业态参数!$Q$21+业态参数!$R$21+业态参数!$S$21) | G21: =收入测算!G21*(业态参数!$Q$21+业态参数!$R$21+业态参数!$S$21) | H21: =收入测算!H21*(业态参数!$Q$21+业态参数!$R$21+业态参数!$S$21) | I21: =收入测算!I21*(业态参数!$Q$21+业态参数!$R$21+业态参数!$S$21) | J21: =收入测算!J21*(业态参数!$Q$21+业态参数!$R$21+业态参数!$S$21) | K21: =收入测算!K21*(业态参数!$Q$21+业态参数!$R$21+业态参数!$S$21) | ... U21: =收入测算!U21*(业态参数!$Q$21+业态参数!$R$21+业态参数!$S$21) | V21: =IF(收入测算!F21=0,0,(收入测算!F21-F21)/收入测算!F21)
A22: 18 | B22: 公园旅拍 | C22: 联营 | D22: =收入测算!D22*(业态参数!$Q$22+业态参数!$R$22+业态参数!$S$22) | E22: =收入测算!E22*(业态参数!$Q$22+业态参数!$R$22+业态参数!$S$22) | F22: =收入测算!F22*(业态参数!$Q$22+业态参数!$R$22+业态参数!$S$22) | G22: =收入测算!G22*(业态参数!$Q$22+业态参数!$R$22+业态参数!$S$22) | H22: =收入测算!H22*(业态参数!$Q$22+业态参数!$R$22+业态参数!$S$22) | I22: =收入测算!I22*(业态参数!$Q$22+业态参数!$R$22+业态参数!$S$22) | J22: =收入测算!J22*(业态参数!$Q$22+业态参数!$R$22+业态参数!$S$22) | K22: =收入测算!K22*(业态参数!$Q$22+业态参数!$R$22+业态参数!$S$22) | ... U22: =收入测算!U22*(业态参数!$Q$22+业态参数!$R$22+业态参数!$S$22) | V22: =IF(收入测算!F22=0,0,(收入测算!F22-F22)/收入测算!F22)
A23: 19 | B23: 园区交通 | C23: 自营 | D23: =收入测算!D23*(业态参数!$Q$23+业态参数!$R$23+业态参数!$S$23) | E23: =收入测算!E23*(业态参数!$Q$23+业态参数!$R$23+业态参数!$S$23) | F23: =收入测算!F23*(业态参数!$Q$23+业态参数!$R$23+业态参数!$S$23) | G23: =收入测算!G23*(业态参数!$Q$23+业态参数!$R$23+业态参数!$S$23) | H23: =收入测算!H23*(业态参数!$Q$23+业态参数!$R$23+业态参数!$S$23) | I23: =收入测算!I23*(业态参数!$Q$23+业态参数!$R$23+业态参数!$S$23) | J23: =收入测算!J23*(业态参数!$Q$23+业态参数!$R$23+业态参数!$S$23) | K23: =收入测算!K23*(业态参数!$Q$23+业态参数!$R$23+业态参数!$S$23) | ... U23: =收入测算!U23*(业态参数!$Q$23+业态参数!$R$23+业态参数!$S$23) | V23: =IF(收入测算!F23=0,0,(收入测算!F23-F23)/收入测算!F23)
A24: 20 | B24: 红色研学/VR展馆 | C24: 自营 | D24: =收入测算!D24*(业态参数!$Q$24+业态参数!$R$24+业态参数!$S$24) | E24: =收入测算!E24*(业态参数!$Q$24+业态参数!$R$24+业态参数!$S$24) | F24: =收入测算!F24*(业态参数!$Q$24+业态参数!$R$24+业态参数!$S$24) | G24: =收入测算!G24*(业态参数!$Q$24+业态参数!$R$24+业态参数!$S$24) | H24: =收入测算!H24*(业态参数!$Q$24+业态参数!$R$24+业态参数!$S$24) | I24: =收入测算!I24*(业态参数!$Q$24+业态参数!$R$24+业态参数!$S$24) | J24: =收入测算!J24*(业态参数!$Q$24+业态参数!$R$24+业态参数!$S$24) | K24: =收入测算!K24*(业态参数!$Q$24+业态参数!$R$24+业态参数!$S$24) | ... U24: =收入测算!U24*(业态参数!$Q$24+业态参数!$R$24+业态参数!$S$24) | V24: =IF(收入测算!F24=0,0,(收入测算!F24-F24)/收入测算!F24)
A25: 21 | B25: 夜游/主题灯光 | C25: 自营 | D25: =收入测算!D25*(业态参数!$Q$25+业态参数!$R$25+业态参数!$S$25) | E25: =收入测算!E25*(业态参数!$Q$25+业态参数!$R$25+业态参数!$S$25) | F25: =收入测算!F25*(业态参数!$Q$25+业态参数!$R$25+业态参数!$S$25) | G25: =收入测算!G25*(业态参数!$Q$25+业态参数!$R$25+业态参数!$S$25) | H25: =收入测算!H25*(业态参数!$Q$25+业态参数!$R$25+业态参数!$S$25) | I25: =收入测算!I25*(业态参数!$Q$25+业态参数!$R$25+业态参数!$S$25) | J25: =收入测算!J25*(业态参数!$Q$25+业态参数!$R$25+业态参数!$S$25) | K25: =收入测算!K25*(业态参数!$Q$25+业态参数!$R$25+业态参数!$S$25) | ... U25: =收入测算!U25*(业态参数!$Q$25+业态参数!$R$25+业态参数!$S$25) | V25: =IF(收入测算!F25=0,0,(收入测算!F25-F25)/收入测算!F25)
A26: 22 | B26: 室内高尔夫 | C26: 联营 | D26: =收入测算!D26*(业态参数!$Q$26+业态参数!$R$26+业态参数!$S$26) | E26: =收入测算!E26*(业态参数!$Q$26+业态参数!$R$26+业态参数!$S$26) | F26: =收入测算!F26*(业态参数!$Q$26+业态参数!$R$26+业态参数!$S$26) | G26: =收入测算!G26*(业态参数!$Q$26+业态参数!$R$26+业态参数!$S$26) | H26: =收入测算!H26*(业态参数!$Q$26+业态参数!$R$26+业态参数!$S$26) | I26: =收入测算!I26*(业态参数!$Q$26+业态参数!$R$26+业态参数!$S$26) | J26: =收入测算!J26*(业态参数!$Q$26+业态参数!$R$26+业态参数!$S$26) | K26: =收入测算!K26*(业态参数!$Q$26+业态参数!$R$26+业态参数!$S$26) | ... U26: =收入测算!U26*(业态参数!$Q$26+业态参数!$R$26+业态参数!$S$26) | V26: =IF(收入测算!F26=0,0,(收入测算!F26-F26)/收入测算!F26)
A27: 23 | B27: 花海摄影 | C27: 自营 | D27: =收入测算!D27*(业态参数!$Q$27+业态参数!$R$27+业态参数!$S$27) | E27: =收入测算!E27*(业态参数!$Q$27+业态参数!$R$27+业态参数!$S$27) | F27: =收入测算!F27*(业态参数!$Q$27+业态参数!$R$27+业态参数!$S$27) | G27: =收入测算!G27*(业态参数!$Q$27+业态参数!$R$27+业态参数!$S$27) | H27: =收入测算!H27*(业态参数!$Q$27+业态参数!$R$27+业态参数!$S$27) | I27: =收入测算!I27*(业态参数!$Q$27+业态参数!$R$27+业态参数!$S$27) | J27: =收入测算!J27*(业态参数!$Q$27+业态参数!$R$27+业态参数!$S$27) | K27: =收入测算!K27*(业态参数!$Q$27+业态参数!$R$27+业态参数!$S$27) | ... U27: =收入测算!U27*(业态参数!$Q$27+业态参数!$R$27+业态参数!$S$27) | V27: =IF(收入测算!F27=0,0,(收入测算!F27-F27)/收入测算!F27)
A28: 24 | B28: 冬季抗联及戏雪 | C28: 联营 | D28: =收入测算!D28*(业态参数!$Q$28+业态参数!$R$28+业态参数!$S$28) | E28: =收入测算!E28*(业态参数!$Q$28+业态参数!$R$28+业态参数!$S$28) | F28: =收入测算!F28*(业态参数!$Q$28+业态参数!$R$28+业态参数!$S$28) | G28: =收入测算!G28*(业态参数!$Q$28+业态参数!$R$28+业态参数!$S$28) | H28: =收入测算!H28*(业态参数!$Q$28+业态参数!$R$28+业态参数!$S$28) | I28: =收入测算!I28*(业态参数!$Q$28+业态参数!$R$28+业态参数!$S$28) | J28: =收入测算!J28*(业态参数!$Q$28+业态参数!$R$28+业态参数!$S$28) | K28: =收入测算!K28*(业态参数!$Q$28+业态参数!$R$28+业态参数!$S$28) | ... U28: =收入测算!U28*(业态参数!$Q$28+业态参数!$R$28+业态参数!$S$28) | V28: =IF(收入测算!F28=0,0,(收入测算!F28-F28)/收入测算!F28)
